<?xml version="1.0" ?>
<!-- =================================================================================== -->
<!-- |    This document was autogenerated by xacro from mobile_robot.urdf.xacro        | -->
<!-- |    EDITING THIS FILE BY HAND IS NOT RECOMMENDED                                 | -->
<!-- =================================================================================== -->
<robot name="mobile_robot">
  <!-- realistic base mass (kg) -->
  <!-- left/right inset -->
  <!-- ===================== -->
  <!-- Base link -->
  <!-- ===================== -->
  <link name="base_link">
    <visual>
      <geometry>
        <box size="0.8 0.5 0.25"/>
      </geometry>
    </visual>
    <collision>
      <geometry>
        <box size="0.8 0.5 0.25"/>
      </geometry>
    </collision>
    <inertial>
      <origin xyz="0 0 0"/>
      <mass value="40.0"/>
      <!-- Computed inertia for rectangular box -->
      <!-- Ixx = 1/12 m (w^2 + h^2) -->
      <!-- Iyy = 1/12 m (l^2 + h^2) -->
      <!-- Izz = 1/12 m (l^2 + w^2) -->
      <inertia ixx="1.0416666666666665" ixy="0.0" ixz="0.0" iyy="2.341666666666667" iyz="0.0" izz="2.966666666666667"/>
    </inertial>
  </link>
  <!-- Gazebo surface and physics settings -->
  <gazebo reference="base_link">
    <mu1 value="0.6"/>
    <mu2 value="0.6"/>
    <kp value="10000000.0"/>
    <kd value="1.0"/>
    <fdir1 value="0 1 0"/>
  </gazebo>
  <link name="front_right_wheel_link">
    <visual>
      <origin rpy="0 0 0" xyz="0 0 0"/>
      <geometry>
        <mesh filename="package://mesh/visual/wheel.dae" scale="1 1 1"/>
      </geometry>
    </visual>
    <collision>
      <geometry>
        <mesh filename="package://mesh/collision/wheel.stl" scale="1 1 1"/>
      </geometry>
    </collision>
    <inertial>
      <origin xyz="0 0 0"/>
      <mass value="2.0"/>
      <inertia ixx="0.042025" ixy="0.0" ixz="0.0" iyy="0.024279" iyz="0.0" izz="0.024279"/>
    </inertial>
  </link>
  <gazebo reference="front_right_wheel_link">
    <mu1 value="0.6"/>
    <mu2 value="0.6"/>
    <kp value="10000000.0"/>
    <kd value="1.0"/>
    <fdir1 value="0 1 0"/>
  </gazebo>
  <link name="front_right_roller15_link">
    <visual>
      <origin rpy="0 0 0" xyz="0 0 0"/>
      <geometry>
        <mesh filename="package://mesh/visual/roller.dae" scale="1 1 1"/>
      </geometry>
    </visual>
    <collision>
      <geometry>
        <mesh filename="package://mesh/collision/roller.stl" scale="1 1 1"/>
      </geometry>
    </collision>
    <inertial>
      <origin xyz="0 0 0"/>
      <mass value="0.3"/>
      <inertia ixx="0.00024000" ixy="0.0" ixz="0.0" iyy="0.00076000" iyz="0.0" izz="0.00076000"/>
    </inertial>
  </link>
  <joint name="front_right_roller15_joint" type="continuous">
    <origin rpy="0.5619350361043127 0.7022987807291682 -0.38630030387691144" xyz="0 0.08176231845901279 -0.03640292955528411"/>
    <axis xyz="1 0 0"/>
    <parent link="front_right_wheel_link"/>
    <child link="front_right_roller15_link"/>
    <dynamics damping="0.001" friction="0.0001"/>
  </joint>
  <transmission name="${name}_roller15_trans">
    <type>transmission_interface/SimpleTransmission</type>
    <joint name="front_right_roller15_joint">
      <hardwareInterface>hardware_interface/EffortJointInterface</hardwareInterface>
    </joint>
    <actuator name="front_right_roller15_motor">
      <hardwareInterface>hardware_interface/EffortJointInterface</hardwareInterface>
      <mechanismReduction>1</mechanismReduction>
    </actuator>
  </transmission>
  <gazebo reference="front_right_roller15_link">
    <mu1 value="0.8"/>
    <mu2 value="0.8"/>
    <kp value="10000000.0"/>
    <kd value="1.0"/>
    <fdir1 value="0 1 0"/>
  </gazebo>
  <link name="front_right_roller14_link">
    <visual>
      <origin rpy="0 0 0" xyz="0 0 0"/>
      <geometry>
        <mesh filename="package://mesh/visual/roller.dae" scale="1 1 1"/>
      </geometry>
    </visual>
    <collision>
      <geometry>
        <mesh filename="package://mesh/collision/roller.stl" scale="1 1 1"/>
      </geometry>
    </collision>
    <inertial>
      <origin xyz="0 0 0"/>
      <mass value="0.3"/>
      <inertia ixx="0.00024000" ixy="0.0" ixz="0.0" iyy="0.00076000" iyz="0.0" izz="0.00076000"/>
    </inertial>
  </link>
  <joint name="front_right_roller14_joint" type="continuous">
    <origin rpy="1.0038406803226874 0.4928592704898482 -0.6390993414905143" xyz="0 0.05988718926911777 -0.06651146188022682"/>
    <axis xyz="1 0 0"/>
    <parent link="front_right_wheel_link"/>
    <child link="front_right_roller14_link"/>
    <dynamics damping="0.001" friction="0.0001"/>
  </joint>
  <transmission name="${name}_roller14_trans">
    <type>transmission_interface/SimpleTransmission</type>
    <joint name="front_right_roller14_joint">
      <hardwareInterface>hardware_interface/EffortJointInterface</hardwareInterface>
    </joint>
    <actuator name="front_right_roller14_motor">
      <hardwareInterface>hardware_interface/EffortJointInterface</hardwareInterface>
      <mechanismReduction>1</mechanismReduction>
    </actuator>
  </transmission>
  <gazebo reference="front_right_roller14_link">
    <mu1 value="0.8"/>
    <mu2 value="0.8"/>
    <kp value="10000000.0"/>
    <kd value="1.0"/>
    <fdir1 value="0 1 0"/>
  </gazebo>
  <link name="front_right_roller13_link">
    <visual>
      <origin rpy="0 0 0" xyz="0 0 0"/>
      <geometry>
        <mesh filename="package://mesh/visual/roller.dae" scale="1 1 1"/>
      </geometry>
    </visual>
    <collision>
      <geometry>
        <mesh filename="package://mesh/collision/roller.stl" scale="1 1 1"/>
      </geometry>
    </collision>
    <inertial>
      <origin xyz="0 0 0"/>
      <mass value="0.3"/>
      <inertia ixx="0.00024000" ixy="0.0" ixz="0.0" iyy="0.00076000" iyz="0.0" izz="0.00076000"/>
    </inertial>
  </link>
  <joint name="front_right_roller13_joint" type="continuous">
    <origin rpy="1.3449626171032882 0.22028527385474703 -0.7603177925108144" xyz="0 0.027657020996557775 -0.08511955820841624"/>
    <axis xyz="1 0 0"/>
    <parent link="front_right_wheel_link"/>
    <child link="front_right_roller13_link"/>
    <dynamics damping="0.001" friction="0.0001"/>
  </joint>
  <transmission name="${name}_roller13_trans">
    <type>transmission_interface/SimpleTransmission</type>
    <joint name="front_right_roller13_joint">
      <hardwareInterface>hardware_interface/EffortJointInterface</hardwareInterface>
    </joint>
    <actuator name="front_right_roller13_motor">
      <hardwareInterface>hardware_interface/EffortJointInterface</hardwareInterface>
      <mechanismReduction>1</mechanismReduction>
    </actuator>
  </transmission>
  <gazebo reference="front_right_roller13_link">
    <mu1 value="0.8"/>
    <mu2 value="0.8"/>
    <kp value="10000000.0"/>
    <kd value="1.0"/>
    <fdir1 value="0 1 0"/>
  </gazebo>
  <link name="front_right_roller12_link">
    <visual>
      <origin rpy="0 0 0" xyz="0 0 0"/>
      <geometry>
        <mesh filename="package://mesh/visual/roller.dae" scale="1 1 1"/>
      </geometry>
    </visual>
    <collision>
      <geometry>
        <mesh filename="package://mesh/collision/roller.stl" scale="1 1 1"/>
      </geometry>
    </collision>
    <inertial>
      <origin xyz="0 0 0"/>
      <mass value="0.3"/>
      <inertia ixx="0.00024000" ixy="0.0" ixz="0.0" iyy="0.00076000" iyz="0.0" izz="0.00076000"/>
    </inertial>
  </link>
  <joint name="front_right_roller12_joint" type="continuous">
    <origin rpy="-1.4966127917301506 -0.07398025001120935 -0.7826515949744619" xyz="0 -0.009355297462454976 -0.08900970963546047"/>
    <axis xyz="1 0 0"/>
    <parent link="front_right_wheel_link"/>
    <child link="front_right_roller12_link"/>
    <dynamics damping="0.001" friction="0.0001"/>
  </joint>
  <transmission name="${name}_roller12_trans">
    <type>transmission_interface/SimpleTransmission</type>
    <joint name="front_right_roller12_joint">
      <hardwareInterface>hardware_interface/EffortJointInterface</hardwareInterface>
    </joint>
    <actuator name="front_right_roller12_motor">
      <hardwareInterface>hardware_interface/EffortJointInterface</hardwareInterface>
      <mechanismReduction>1</mechanismReduction>
    </actuator>
  </transmission>
  <gazebo reference="front_right_roller12_link">
    <mu1 value="0.8"/>
    <mu2 value="0.8"/>
    <kp value="10000000.0"/>
    <kd value="1.0"/>
    <fdir1 value="0 1 0"/>
  </gazebo>
  <link name="front_right_roller11_link">
    <visual>
      <origin rpy="0 0 0" xyz="0 0 0"/>
      <geometry>
        <mesh filename="package://mesh/visual/roller.dae" scale="1 1 1"/>
      </geometry>
    </visual>
    <collision>
      <geometry>
        <mesh filename="package://mesh/collision/roller.stl" scale="1 1 1"/>
      </geometry>
    </collision>
    <inertial>
      <origin xyz="0 0 0"/>
      <mass value="0.3"/>
      <inertia ixx="0.00024000" ixy="0.0" ixz="0.0" iyy="0.00076000" iyz="0.0" izz="0.00076000"/>
    </inertial>
  </link>
  <joint name="front_right_roller11_joint" type="continuous">
    <origin rpy="-1.1831996401397156 -0.3613671239067081 -0.7137243789447655" xyz="0 -0.04475000000000004 -0.07750927363870723"/>
    <axis xyz="1 0 0"/>
    <parent link="front_right_wheel_link"/>
    <child link="front_right_roller11_link"/>
    <dynamics damping="0.001" friction="0.0001"/>
  </joint>
  <transmission name="${name}_roller11_trans">
    <type>transmission_interface/SimpleTransmission</type>
    <joint name="front_right_roller11_joint">
      <hardwareInterface>hardware_interface/EffortJointInterface</hardwareInterface>
    </joint>
    <actuator name="front_right_roller11_motor">
      <hardwareInterface>hardware_interface/EffortJointInterface</hardwareInterface>
      <mechanismReduction>1</mechanismReduction>
    </actuator>
  </transmission>
  <gazebo reference="front_right_roller11_link">
    <mu1 value="0.8"/>
    <mu2 value="0.8"/>
    <kp value="10000000.0"/>
    <kd value="1.0"/>
    <fdir1 value="0 1 0"/>
  </gazebo>
  <link name="front_right_roller10_link">
    <visual>
      <origin rpy="0 0 0" xyz="0 0 0"/>
      <geometry>
        <mesh filename="package://mesh/visual/roller.dae" scale="1 1 1"/>
      </geometry>
    </visual>
    <collision>
      <geometry>
        <mesh filename="package://mesh/collision/roller.stl" scale="1 1 1"/>
      </geometry>
    </collision>
    <inertial>
      <origin xyz="0 0 0"/>
      <mass value="0.3"/>
      <inertia ixx="0.00024000" ixy="0.0" ixz="0.0" iyy="0.00076000" iyz="0.0" izz="0.00076000"/>
    </inertial>
  </link>
  <joint name="front_right_roller10_joint" type="continuous">
    <origin rpy="-0.7989541677433551 -0.6090169187607924 -0.5313896516603533" xyz="0 -0.0724070209965578 -0.05260678008017634"/>
    <axis xyz="1 0 0"/>
    <parent link="front_right_wheel_link"/>
    <child link="front_right_roller10_link"/>
    <dynamics damping="0.001" friction="0.0001"/>
  </joint>
  <transmission name="${name}_roller10_trans">
    <type>transmission_interface/SimpleTransmission</type>
    <joint name="front_right_roller10_joint">
      <hardwareInterface>hardware_interface/EffortJointInterface</hardwareInterface>
    </joint>
    <actuator name="front_right_roller10_motor">
      <hardwareInterface>hardware_interface/EffortJointInterface</hardwareInterface>
      <mechanismReduction>1</mechanismReduction>
    </actuator>
  </transmission>
  <gazebo reference="front_right_roller10_link">
    <mu1 value="0.8"/>
    <mu2 value="0.8"/>
    <kp value="10000000.0"/>
    <kd value="1.0"/>
    <fdir1 value="0 1 0"/>
  </gazebo>
  <link name="front_right_roller9_link">
    <visual>
      <origin rpy="0 0 0" xyz="0 0 0"/>
      <geometry>
        <mesh filename="package://mesh/visual/roller.dae" scale="1 1 1"/>
      </geometry>
    </visual>
    <collision>
      <geometry>
        <mesh filename="package://mesh/collision/roller.stl" scale="1 1 1"/>
      </geometry>
    </collision>
    <inertial>
      <origin xyz="0 0 0"/>
      <mass value="0.3"/>
      <inertia ixx="0.00024000" ixy="0.0" ixz="0.0" iyy="0.00076000" iyz="0.0" izz="0.00076000"/>
    </inertial>
  </link>
  <joint name="front_right_roller9_joint" type="continuous">
    <origin rpy="-0.29200750368454736 -0.7637777909460687 -0.20499125187874406" xyz="0 -0.08754421026567559 -0.018608096328189477"/>
    <axis xyz="1 0 0"/>
    <parent link="front_right_wheel_link"/>
    <child link="front_right_roller9_link"/>
    <dynamics damping="0.001" friction="0.0001"/>
  </joint>
  <transmission name="${name}_roller9_trans">
    <type>transmission_interface/SimpleTransmission</type>
    <joint name="front_right_roller9_joint">
      <hardwareInterface>hardware_interface/EffortJointInterface</hardwareInterface>
    </joint>
    <actuator name="front_right_roller9_motor">
      <hardwareInterface>hardware_interface/EffortJointInterface</hardwareInterface>
      <mechanismReduction>1</mechanismReduction>
    </actuator>
  </transmission>
  <gazebo reference="front_right_roller9_link">
    <mu1 value="0.8"/>
    <mu2 value="0.8"/>
    <kp value="10000000.0"/>
    <kd value="1.0"/>
    <fdir1 value="0 1 0"/>
  </gazebo>
  <link name="front_right_roller8_link">
    <visual>
      <origin rpy="0 0 0" xyz="0 0 0"/>
      <geometry>
        <mesh filename="package://mesh/visual/roller.dae" scale="1 1 1"/>
      </geometry>
    </visual>
    <collision>
      <geometry>
        <mesh filename="package://mesh/collision/roller.stl" scale="1 1 1"/>
      </geometry>
    </collision>
    <inertial>
      <origin xyz="0 0 0"/>
      <mass value="0.3"/>
      <inertia ixx="0.00024000" ixy="0.0" ixz="0.0" iyy="0.00076000" iyz="0.0" izz="0.00076000"/>
    </inertial>
  </link>
  <joint name="front_right_roller8_joint" type="continuous">
    <origin rpy="0.2920075036845471 -0.7637777909460687 0.20499125187874387" xyz="0 -0.0875442102656756 0.01860809632818946"/>
    <axis xyz="1 0 0"/>
    <parent link="front_right_wheel_link"/>
    <child link="front_right_roller8_link"/>
    <dynamics damping="0.001" friction="0.0001"/>
  </joint>
  <transmission name="${name}_roller8_trans">
    <type>transmission_interface/SimpleTransmission</type>
    <joint name="front_right_roller8_joint">
      <hardwareInterface>hardware_interface/EffortJointInterface</hardwareInterface>
    </joint>
    <actuator name="front_right_roller8_motor">
      <hardwareInterface>hardware_interface/EffortJointInterface</hardwareInterface>
      <mechanismReduction>1</mechanismReduction>
    </actuator>
  </transmission>
  <gazebo reference="front_right_roller8_link">
    <mu1 value="0.8"/>
    <mu2 value="0.8"/>
    <kp value="10000000.0"/>
    <kd value="1.0"/>
    <fdir1 value="0 1 0"/>
  </gazebo>
  <link name="front_right_roller7_link">
    <visual>
      <origin rpy="0 0 0" xyz="0 0 0"/>
      <geometry>
        <mesh filename="package://mesh/visual/roller.dae" scale="1 1 1"/>
      </geometry>
    </visual>
    <collision>
      <geometry>
        <mesh filename="package://mesh/collision/roller.stl" scale="1 1 1"/>
      </geometry>
    </collision>
    <inertial>
      <origin xyz="0 0 0"/>
      <mass value="0.3"/>
      <inertia ixx="0.00024000" ixy="0.0" ixz="0.0" iyy="0.00076000" iyz="0.0" izz="0.00076000"/>
    </inertial>
  </link>
  <joint name="front_right_roller7_joint" type="continuous">
    <origin rpy="0.7989541677433554 -0.6090169187607923 0.5313896516603536" xyz="0 -0.07240702099655778 0.05260678008017635"/>
    <axis xyz="1 0 0"/>
    <parent link="front_right_wheel_link"/>
    <child link="front_right_roller7_link"/>
    <dynamics damping="0.001" friction="0.0001"/>
  </joint>
  <transmission name="${name}_roller7_trans">
    <type>transmission_interface/SimpleTransmission</type>
    <joint name="front_right_roller7_joint">
      <hardwareInterface>hardware_interface/EffortJointInterface</hardwareInterface>
    </joint>
    <actuator name="front_right_roller7_motor">
      <hardwareInterface>hardware_interface/EffortJointInterface</hardwareInterface>
      <mechanismReduction>1</mechanismReduction>
    </actuator>
  </transmission>
  <gazebo reference="front_right_roller7_link">
    <mu1 value="0.8"/>
    <mu2 value="0.8"/>
    <kp value="10000000.0"/>
    <kd value="1.0"/>
    <fdir1 value="0 1 0"/>
  </gazebo>
  <link name="front_right_roller6_link">
    <visual>
      <origin rpy="0 0 0" xyz="0 0 0"/>
      <geometry>
        <mesh filename="package://mesh/visual/roller.dae" scale="1 1 1"/>
      </geometry>
    </visual>
    <collision>
      <geometry>
        <mesh filename="package://mesh/collision/roller.stl" scale="1 1 1"/>
      </geometry>
    </collision>
    <inertial>
      <origin xyz="0 0 0"/>
      <mass value="0.3"/>
      <inertia ixx="0.00024000" ixy="0.0" ixz="0.0" iyy="0.00076000" iyz="0.0" izz="0.00076000"/>
    </inertial>
  </link>
  <joint name="front_right_roller6_joint" type="continuous">
    <origin rpy="1.1831996401397162 -0.3613671239067076 0.7137243789447657" xyz="0 -0.04474999999999998 0.07750927363870726"/>
    <axis xyz="1 0 0"/>
    <parent link="front_right_wheel_link"/>
    <child link="front_right_roller6_link"/>
    <dynamics damping="0.001" friction="0.0001"/>
  </joint>
  <transmission name="${name}_roller6_trans">
    <type>transmission_interface/SimpleTransmission</type>
    <joint name="front_right_roller6_joint">
      <hardwareInterface>hardware_interface/EffortJointInterface</hardwareInterface>
    </joint>
    <actuator name="front_right_roller6_motor">
      <hardwareInterface>hardware_interface/EffortJointInterface</hardwareInterface>
      <mechanismReduction>1</mechanismReduction>
    </actuator>
  </transmission>
  <gazebo reference="front_right_roller6_link">
    <mu1 value="0.8"/>
    <mu2 value="0.8"/>
    <kp value="10000000.0"/>
    <kd value="1.0"/>
    <fdir1 value="0 1 0"/>
  </gazebo>
  <link name="front_right_roller5_link">
    <visual>
      <origin rpy="0 0 0" xyz="0 0 0"/>
      <geometry>
        <mesh filename="package://mesh/visual/roller.dae" scale="1 1 1"/>
      </geometry>
    </visual>
    <collision>
      <geometry>
        <mesh filename="package://mesh/collision/roller.stl" scale="1 1 1"/>
      </geometry>
    </collision>
    <inertial>
      <origin xyz="0 0 0"/>
      <mass value="0.3"/>
      <inertia ixx="0.00024000" ixy="0.0" ixz="0.0" iyy="0.00076000" iyz="0.0" izz="0.00076000"/>
    </inertial>
  </link>
  <joint name="front_right_roller5_joint" type="continuous">
    <origin rpy="1.4966127917301504 -0.07398025001120949 0.7826515949744619" xyz="0 -0.009355297462454993 0.08900970963546045"/>
    <axis xyz="1 0 0"/>
    <parent link="front_right_wheel_link"/>
    <child link="front_right_roller5_link"/>
    <dynamics damping="0.001" friction="0.0001"/>
  </joint>
  <transmission name="${name}_roller5_trans">
    <type>transmission_interface/SimpleTransmission</type>
    <joint name="front_right_roller5_joint">
      <hardwareInterface>hardware_interface/EffortJointInterface</hardwareInterface>
    </joint>
    <actuator name="front_right_roller5_motor">
      <hardwareInterface>hardware_interface/EffortJointInterface</hardwareInterface>
      <mechanismReduction>1</mechanismReduction>
    </actuator>
  </transmission>
  <gazebo reference="front_right_roller5_link">
    <mu1 value="0.8"/>
    <mu2 value="0.8"/>
    <kp value="10000000.0"/>
    <kd value="1.0"/>
    <fdir1 value="0 1 0"/>
  </gazebo>
  <link name="front_right_roller4_link">
    <visual>
      <origin rpy="0 0 0" xyz="0 0 0"/>
      <geometry>
        <mesh filename="package://mesh/visual/roller.dae" scale="1 1 1"/>
      </geometry>
    </visual>
    <collision>
      <geometry>
        <mesh filename="package://mesh/collision/roller.stl" scale="1 1 1"/>
      </geometry>
    </collision>
    <inertial>
      <origin xyz="0 0 0"/>
      <mass value="0.3"/>
      <inertia ixx="0.00024000" ixy="0.0" ixz="0.0" iyy="0.00076000" iyz="0.0" izz="0.00076000"/>
    </inertial>
  </link>
  <joint name="front_right_roller4_joint" type="continuous">
    <origin rpy="-1.3449626171032882 0.2202852738547472 0.7603177925108144" xyz="0 0.027657020996557796 0.08511955820841624"/>
    <axis xyz="1 0 0"/>
    <parent link="front_right_wheel_link"/>
    <child link="front_right_roller4_link"/>
    <dynamics damping="0.001" friction="0.0001"/>
  </joint>
  <transmission name="${name}_roller4_trans">
    <type>transmission_interface/SimpleTransmission</type>
    <joint name="front_right_roller4_joint">
      <hardwareInterface>hardware_interface/EffortJointInterface</hardwareInterface>
    </joint>
    <actuator name="front_right_roller4_motor">
      <hardwareInterface>hardware_interface/EffortJointInterface</hardwareInterface>
      <mechanismReduction>1</mechanismReduction>
    </actuator>
  </transmission>
  <gazebo reference="front_right_roller4_link">
    <mu1 value="0.8"/>
    <mu2 value="0.8"/>
    <kp value="10000000.0"/>
    <kd value="1.0"/>
    <fdir1 value="0 1 0"/>
  </gazebo>
  <link name="front_right_roller3_link">
    <visual>
      <origin rpy="0 0 0" xyz="0 0 0"/>
      <geometry>
        <mesh filename="package://mesh/visual/roller.dae" scale="1 1 1"/>
      </geometry>
    </visual>
    <collision>
      <geometry>
        <mesh filename="package://mesh/collision/roller.stl" scale="1 1 1"/>
      </geometry>
    </collision>
    <inertial>
      <origin xyz="0 0 0"/>
      <mass value="0.3"/>
      <inertia ixx="0.00024000" ixy="0.0" ixz="0.0" iyy="0.00076000" iyz="0.0" izz="0.00076000"/>
    </inertial>
  </link>
  <joint name="front_right_roller3_joint" type="continuous">
    <origin rpy="-1.0038406803226867 0.4928592704898485 0.6390993414905141" xyz="0 0.05988718926911781 0.06651146188022679"/>
    <axis xyz="1 0 0"/>
    <parent link="front_right_wheel_link"/>
    <child link="front_right_roller3_link"/>
    <dynamics damping="0.001" friction="0.0001"/>
  </joint>
  <transmission name="${name}_roller3_trans">
    <type>transmission_interface/SimpleTransmission</type>
    <joint name="front_right_roller3_joint">
      <hardwareInterface>hardware_interface/EffortJointInterface</hardwareInterface>
    </joint>
    <actuator name="front_right_roller3_motor">
      <hardwareInterface>hardware_interface/EffortJointInterface</hardwareInterface>
      <mechanismReduction>1</mechanismReduction>
    </actuator>
  </transmission>
  <gazebo reference="front_right_roller3_link">
    <mu1 value="0.8"/>
    <mu2 value="0.8"/>
    <kp value="10000000.0"/>
    <kd value="1.0"/>
    <fdir1 value="0 1 0"/>
  </gazebo>
  <link name="front_right_roller2_link">
    <visual>
      <origin rpy="0 0 0" xyz="0 0 0"/>
      <geometry>
        <mesh filename="package://mesh/visual/roller.dae" scale="1 1 1"/>
      </geometry>
    </visual>
    <collision>
      <geometry>
        <mesh filename="package://mesh/collision/roller.stl" scale="1 1 1"/>
      </geometry>
    </collision>
    <inertial>
      <origin xyz="0 0 0"/>
      <mass value="0.3"/>
      <inertia ixx="0.00024000" ixy="0.0" ixz="0.0" iyy="0.00076000" iyz="0.0" izz="0.00076000"/>
    </inertial>
  </link>
  <joint name="front_right_roller2_joint" type="continuous">
    <origin rpy="-0.5619350361043128 0.702298780729168 0.3863003038769115" xyz="0 0.08176231845901277 0.03640292955528412"/>
    <axis xyz="1 0 0"/>
    <parent link="front_right_wheel_link"/>
    <child link="front_right_roller2_link"/>
    <dynamics damping="0.001" friction="0.0001"/>
  </joint>
  <transmission name="${name}_roller2_trans">
    <type>transmission_interface/SimpleTransmission</type>
    <joint name="front_right_roller2_joint">
      <hardwareInterface>hardware_interface/EffortJointInterface</hardwareInterface>
    </joint>
    <actuator name="front_right_roller2_motor">
      <hardwareInterface>hardware_interface/EffortJointInterface</hardwareInterface>
      <mechanismReduction>1</mechanismReduction>
    </actuator>
  </transmission>
  <gazebo reference="front_right_roller2_link">
    <mu1 value="0.8"/>
    <mu2 value="0.8"/>
    <kp value="10000000.0"/>
    <kd value="1.0"/>
    <fdir1 value="0 1 0"/>
  </gazebo>
  <link name="front_right_roller1_link">
    <visual>
      <origin rpy="0 0 0" xyz="0 0 0"/>
      <geometry>
        <mesh filename="package://mesh/visual/roller.dae" scale="1 1 1"/>
      </geometry>
    </visual>
    <collision>
      <geometry>
        <mesh filename="package://mesh/collision/roller.stl" scale="1 1 1"/>
      </geometry>
    </collision>
    <inertial>
      <origin xyz="0 0 0"/>
      <mass value="0.3"/>
      <inertia ixx="0.00024000" ixy="0.0" ixz="0.0" iyy="0.00076000" iyz="0.0" izz="0.00076000"/>
    </inertial>
  </link>
  <joint name="front_right_roller1_joint" type="continuous">
    <origin rpy="-0.0 0.7853981633974482 0.0" xyz="0 0.0895 0.0"/>
    <axis xyz="1 0 0"/>
    <parent link="front_right_wheel_link"/>
    <child link="front_right_roller1_link"/>
    <dynamics damping="0.001" friction="0.0001"/>
  </joint>
  <transmission name="${name}_roller1_trans">
    <type>transmission_interface/SimpleTransmission</type>
    <joint name="front_right_roller1_joint">
      <hardwareInterface>hardware_interface/EffortJointInterface</hardwareInterface>
    </joint>
    <actuator name="front_right_roller1_motor">
      <hardwareInterface>hardware_interface/EffortJointInterface</hardwareInterface>
      <mechanismReduction>1</mechanismReduction>
    </actuator>
  </transmission>
  <gazebo reference="front_right_roller1_link">
    <mu1 value="0.8"/>
    <mu2 value="0.8"/>
    <kp value="10000000.0"/>
    <kd value="1.0"/>
    <fdir1 value="0 1 0"/>
  </gazebo>
  <transmission name="front_right_wheel_trans">
    <type>transmission_interface/SimpleTransmission</type>
    <joint name="front_right_wheel_joint">
      <hardwareInterface>hardware_interface/EffortJointInterface</hardwareInterface>
    </joint>
    <actuator name="front_right_wheel_motor">
      <hardwareInterface>hardware_interface/EffortJointInterface</hardwareInterface>
      <mechanismReduction>1</mechanismReduction>
    </actuator>
  </transmission>
  <link name="front_left_wheel_link">
    <visual>
      <origin rpy="0 0 0" xyz="0 0 0"/>
      <geometry>
        <mesh filename="package://mesh/visual/wheel.dae" scale="-1 1 1"/>
      </geometry>
    </visual>
    <collision>
      <geometry>
        <mesh filename="package://mesh/collision/wheel.stl" scale="-1 1 1"/>
      </geometry>
    </collision>
    <inertial>
      <origin xyz="0 0 0"/>
      <mass value="2.0"/>
      <inertia ixx="0.042025" ixy="0.0" ixz="0.0" iyy="0.024279" iyz="0.0" izz="0.024279"/>
    </inertial>
  </link>
  <gazebo reference="front_left_wheel_link">
    <mu1 value="0.6"/>
    <mu2 value="0.6"/>
    <kp value="10000000.0"/>
    <kd value="1.0"/>
    <fdir1 value="0 1 0"/>
  </gazebo>
  <link name="front_left_roller15_link">
    <visual>
      <origin rpy="0 0 0" xyz="0 0 0"/>
      <geometry>
        <mesh filename="package://mesh/visual/roller.dae" scale="1 1 1"/>
      </geometry>
    </visual>
    <collision>
      <geometry>
        <mesh filename="package://mesh/collision/roller.stl" scale="1 1 1"/>
      </geometry>
    </collision>
    <inertial>
      <origin xyz="0 0 0"/>
      <mass value="0.3"/>
      <inertia ixx="0.00024000" ixy="0.0" ixz="0.0" iyy="0.00076000" iyz="0.0" izz="0.00076000"/>
    </inertial>
  </link>
  <joint name="front_left_roller15_joint" type="continuous">
    <origin rpy="0.5619350361043127 -0.7022987807291682 0.38630030387691144" xyz="0 0.08176231845901279 -0.03640292955528411"/>
    <axis xyz="1 0 0"/>
    <parent link="front_left_wheel_link"/>
    <child link="front_left_roller15_link"/>
    <dynamics damping="0.001" friction="0.0001"/>
  </joint>
  <transmission name="${name}_roller15_trans">
    <type>transmission_interface/SimpleTransmission</type>
    <joint name="front_left_roller15_joint">
      <hardwareInterface>hardware_interface/EffortJointInterface</hardwareInterface>
    </joint>
    <actuator name="front_left_roller15_motor">
      <hardwareInterface>hardware_interface/EffortJointInterface</hardwareInterface>
      <mechanismReduction>1</mechanismReduction>
    </actuator>
  </transmission>
  <gazebo reference="front_left_roller15_link">
    <mu1 value="0.8"/>
    <mu2 value="0.8"/>
    <kp value="10000000.0"/>
    <kd value="1.0"/>
    <fdir1 value="0 1 0"/>
  </gazebo>
  <link name="front_left_roller14_link">
    <visual>
      <origin rpy="0 0 0" xyz="0 0 0"/>
      <geometry>
        <mesh filename="package://mesh/visual/roller.dae" scale="1 1 1"/>
      </geometry>
    </visual>
    <collision>
      <geometry>
        <mesh filename="package://mesh/collision/roller.stl" scale="1 1 1"/>
      </geometry>
    </collision>
    <inertial>
      <origin xyz="0 0 0"/>
      <mass value="0.3"/>
      <inertia ixx="0.00024000" ixy="0.0" ixz="0.0" iyy="0.00076000" iyz="0.0" izz="0.00076000"/>
    </inertial>
  </link>
  <joint name="front_left_roller14_joint" type="continuous">
    <origin rpy="1.0038406803226874 -0.4928592704898482 0.6390993414905143" xyz="0 0.05988718926911777 -0.06651146188022682"/>
    <axis xyz="1 0 0"/>
    <parent link="front_left_wheel_link"/>
    <child link="front_left_roller14_link"/>
    <dynamics damping="0.001" friction="0.0001"/>
  </joint>
  <transmission name="${name}_roller14_trans">
    <type>transmission_interface/SimpleTransmission</type>
    <joint name="front_left_roller14_joint">
      <hardwareInterface>hardware_interface/EffortJointInterface</hardwareInterface>
    </joint>
    <actuator name="front_left_roller14_motor">
      <hardwareInterface>hardware_interface/EffortJointInterface</hardwareInterface>
      <mechanismReduction>1</mechanismReduction>
    </actuator>
  </transmission>
  <gazebo reference="front_left_roller14_link">
    <mu1 value="0.8"/>
    <mu2 value="0.8"/>
    <kp value="10000000.0"/>
    <kd value="1.0"/>
    <fdir1 value="0 1 0"/>
  </gazebo>
  <link name="front_left_roller13_link">
    <visual>
      <origin rpy="0 0 0" xyz="0 0 0"/>
      <geometry>
        <mesh filename="package://mesh/visual/roller.dae" scale="1 1 1"/>
      </geometry>
    </visual>
    <collision>
      <geometry>
        <mesh filename="package://mesh/collision/roller.stl" scale="1 1 1"/>
      </geometry>
    </collision>
    <inertial>
      <origin xyz="0 0 0"/>
      <mass value="0.3"/>
      <inertia ixx="0.00024000" ixy="0.0" ixz="0.0" iyy="0.00076000" iyz="0.0" izz="0.00076000"/>
    </inertial>
  </link>
  <joint name="front_left_roller13_joint" type="continuous">
    <origin rpy="1.3449626171032882 -0.22028527385474703 0.7603177925108144" xyz="0 0.027657020996557775 -0.08511955820841624"/>
    <axis xyz="1 0 0"/>
    <parent link="front_left_wheel_link"/>
    <child link="front_left_roller13_link"/>
    <dynamics damping="0.001" friction="0.0001"/>
  </joint>
  <transmission name="${name}_roller13_trans">
    <type>transmission_interface/SimpleTransmission</type>
    <joint name="front_left_roller13_joint">
      <hardwareInterface>hardware_interface/EffortJointInterface</hardwareInterface>
    </joint>
    <actuator name="front_left_roller13_motor">
      <hardwareInterface>hardware_interface/EffortJointInterface</hardwareInterface>
      <mechanismReduction>1</mechanismReduction>
    </actuator>
  </transmission>
  <gazebo reference="front_left_roller13_link">
    <mu1 value="0.8"/>
    <mu2 value="0.8"/>
    <kp value="10000000.0"/>
    <kd value="1.0"/>
    <fdir1 value="0 1 0"/>
  </gazebo>
  <link name="front_left_roller12_link">
    <visual>
      <origin rpy="0 0 0" xyz="0 0 0"/>
      <geometry>
        <mesh filename="package://mesh/visual/roller.dae" scale="1 1 1"/>
      </geometry>
    </visual>
    <collision>
      <geometry>
        <mesh filename="package://mesh/collision/roller.stl" scale="1 1 1"/>
      </geometry>
    </collision>
    <inertial>
      <origin xyz="0 0 0"/>
      <mass value="0.3"/>
      <inertia ixx="0.00024000" ixy="0.0" ixz="0.0" iyy="0.00076000" iyz="0.0" izz="0.00076000"/>
    </inertial>
  </link>
  <joint name="front_left_roller12_joint" type="continuous">
    <origin rpy="-1.4966127917301506 0.07398025001120935 0.7826515949744619" xyz="0 -0.009355297462454976 -0.08900970963546047"/>
    <axis xyz="1 0 0"/>
    <parent link="front_left_wheel_link"/>
    <child link="front_left_roller12_link"/>
    <dynamics damping="0.001" friction="0.0001"/>
  </joint>
  <transmission name="${name}_roller12_trans">
    <type>transmission_interface/SimpleTransmission</type>
    <joint name="front_left_roller12_joint">
      <hardwareInterface>hardware_interface/EffortJointInterface</hardwareInterface>
    </joint>
    <actuator name="front_left_roller12_motor">
      <hardwareInterface>hardware_interface/EffortJointInterface</hardwareInterface>
      <mechanismReduction>1</mechanismReduction>
    </actuator>
  </transmission>
  <gazebo reference="front_left_roller12_link">
    <mu1 value="0.8"/>
    <mu2 value="0.8"/>
    <kp value="10000000.0"/>
    <kd value="1.0"/>
    <fdir1 value="0 1 0"/>
  </gazebo>
  <link name="front_left_roller11_link">
    <visual>
      <origin rpy="0 0 0" xyz="0 0 0"/>
      <geometry>
        <mesh filename="package://mesh/visual/roller.dae" scale="1 1 1"/>
      </geometry>
    </visual>
    <collision>
      <geometry>
        <mesh filename="package://mesh/collision/roller.stl" scale="1 1 1"/>
      </geometry>
    </collision>
    <inertial>
      <origin xyz="0 0 0"/>
      <mass value="0.3"/>
      <inertia ixx="0.00024000" ixy="0.0" ixz="0.0" iyy="0.00076000" iyz="0.0" izz="0.00076000"/>
    </inertial>
  </link>
  <joint name="front_left_roller11_joint" type="continuous">
    <origin rpy="-1.1831996401397156 0.3613671239067081 0.7137243789447655" xyz="0 -0.04475000000000004 -0.07750927363870723"/>
    <axis xyz="1 0 0"/>
    <parent link="front_left_wheel_link"/>
    <child link="front_left_roller11_link"/>
    <dynamics damping="0.001" friction="0.0001"/>
  </joint>
  <transmission name="${name}_roller11_trans">
    <type>transmission_interface/SimpleTransmission</type>
    <joint name="front_left_roller11_joint">
      <hardwareInterface>hardware_interface/EffortJointInterface</hardwareInterface>
    </joint>
    <actuator name="front_left_roller11_motor">
      <hardwareInterface>hardware_interface/EffortJointInterface</hardwareInterface>
      <mechanismReduction>1</mechanismReduction>
    </actuator>
  </transmission>
  <gazebo reference="front_left_roller11_link">
    <mu1 value="0.8"/>
    <mu2 value="0.8"/>
    <kp value="10000000.0"/>
    <kd value="1.0"/>
    <fdir1 value="0 1 0"/>
  </gazebo>
  <link name="front_left_roller10_link">
    <visual>
      <origin rpy="0 0 0" xyz="0 0 0"/>
      <geometry>
        <mesh filename="package://mesh/visual/roller.dae" scale="1 1 1"/>
      </geometry>
    </visual>
    <collision>
      <geometry>
        <mesh filename="package://mesh/collision/roller.stl" scale="1 1 1"/>
      </geometry>
    </collision>
    <inertial>
      <origin xyz="0 0 0"/>
      <mass value="0.3"/>
      <inertia ixx="0.00024000" ixy="0.0" ixz="0.0" iyy="0.00076000" iyz="0.0" izz="0.00076000"/>
    </inertial>
  </link>
  <joint name="front_left_roller10_joint" type="continuous">
    <origin rpy="-0.7989541677433551 0.6090169187607924 0.5313896516603533" xyz="0 -0.0724070209965578 -0.05260678008017634"/>
    <axis xyz="1 0 0"/>
    <parent link="front_left_wheel_link"/>
    <child link="front_left_roller10_link"/>
    <dynamics damping="0.001" friction="0.0001"/>
  </joint>
  <transmission name="${name}_roller10_trans">
    <type>transmission_interface/SimpleTransmission</type>
    <joint name="front_left_roller10_joint">
      <hardwareInterface>hardware_interface/EffortJointInterface</hardwareInterface>
    </joint>
    <actuator name="front_left_roller10_motor">
      <hardwareInterface>hardware_interface/EffortJointInterface</hardwareInterface>
      <mechanismReduction>1</mechanismReduction>
    </actuator>
  </transmission>
  <gazebo reference="front_left_roller10_link">
    <mu1 value="0.8"/>
    <mu2 value="0.8"/>
    <kp value="10000000.0"/>
    <kd value="1.0"/>
    <fdir1 value="0 1 0"/>
  </gazebo>
  <link name="front_left_roller9_link">
    <visual>
      <origin rpy="0 0 0" xyz="0 0 0"/>
      <geometry>
        <mesh filename="package://mesh/visual/roller.dae" scale="1 1 1"/>
      </geometry>
    </visual>
    <collision>
      <geometry>
        <mesh filename="package://mesh/collision/roller.stl" scale="1 1 1"/>
      </geometry>
    </collision>
    <inertial>
      <origin xyz="0 0 0"/>
      <mass value="0.3"/>
      <inertia ixx="0.00024000" ixy="0.0" ixz="0.0" iyy="0.00076000" iyz="0.0" izz="0.00076000"/>
    </inertial>
  </link>
  <joint name="front_left_roller9_joint" type="continuous">
    <origin rpy="-0.29200750368454736 0.7637777909460687 0.20499125187874406" xyz="0 -0.08754421026567559 -0.018608096328189477"/>
    <axis xyz="1 0 0"/>
    <parent link="front_left_wheel_link"/>
    <child link="front_left_roller9_link"/>
    <dynamics damping="0.001" friction="0.0001"/>
  </joint>
  <transmission name="${name}_roller9_trans">
    <type>transmission_interface/SimpleTransmission</type>
    <joint name="front_left_roller9_joint">
      <hardwareInterface>hardware_interface/EffortJointInterface</hardwareInterface>
    </joint>
    <actuator name="front_left_roller9_motor">
      <hardwareInterface>hardware_interface/EffortJointInterface</hardwareInterface>
      <mechanismReduction>1</mechanismReduction>
    </actuator>
  </transmission>
  <gazebo reference="front_left_roller9_link">
    <mu1 value="0.8"/>
    <mu2 value="0.8"/>
    <kp value="10000000.0"/>
    <kd value="1.0"/>
    <fdir1 value="0 1 0"/>
  </gazebo>
  <link name="front_left_roller8_link">
    <visual>
      <origin rpy="0 0 0" xyz="0 0 0"/>
      <geometry>
        <mesh filename="package://mesh/visual/roller.dae" scale="1 1 1"/>
      </geometry>
    </visual>
    <collision>
      <geometry>
        <mesh filename="package://mesh/collision/roller.stl" scale="1 1 1"/>
      </geometry>
    </collision>
    <inertial>
      <origin xyz="0 0 0"/>
      <mass value="0.3"/>
      <inertia ixx="0.00024000" ixy="0.0" ixz="0.0" iyy="0.00076000" iyz="0.0" izz="0.00076000"/>
    </inertial>
  </link>
  <joint name="front_left_roller8_joint" type="continuous">
    <origin rpy="0.2920075036845471 0.7637777909460687 -0.20499125187874387" xyz="0 -0.0875442102656756 0.01860809632818946"/>
    <axis xyz="1 0 0"/>
    <parent link="front_left_wheel_link"/>
    <child link="front_left_roller8_link"/>
    <dynamics damping="0.001" friction="0.0001"/>
  </joint>
  <transmission name="${name}_roller8_trans">
    <type>transmission_interface/SimpleTransmission</type>
    <joint name="front_left_roller8_joint">
      <hardwareInterface>hardware_interface/EffortJointInterface</hardwareInterface>
    </joint>
    <actuator name="front_left_roller8_motor">
      <hardwareInterface>hardware_interface/EffortJointInterface</hardwareInterface>
      <mechanismReduction>1</mechanismReduction>
    </actuator>
  </transmission>
  <gazebo reference="front_left_roller8_link">
    <mu1 value="0.8"/>
    <mu2 value="0.8"/>
    <kp value="10000000.0"/>
    <kd value="1.0"/>
    <fdir1 value="0 1 0"/>
  </gazebo>
  <link name="front_left_roller7_link">
    <visual>
      <origin rpy="0 0 0" xyz="0 0 0"/>
      <geometry>
        <mesh filename="package://mesh/visual/roller.dae" scale="1 1 1"/>
      </geometry>
    </visual>
    <collision>
      <geometry>
        <mesh filename="package://mesh/collision/roller.stl" scale="1 1 1"/>
      </geometry>
    </collision>
    <inertial>
      <origin xyz="0 0 0"/>
      <mass value="0.3"/>
      <inertia ixx="0.00024000" ixy="0.0" ixz="0.0" iyy="0.00076000" iyz="0.0" izz="0.00076000"/>
    </inertial>
  </link>
  <joint name="front_left_roller7_joint" type="continuous">
    <origin rpy="0.7989541677433554 0.6090169187607923 -0.5313896516603536" xyz="0 -0.07240702099655778 0.05260678008017635"/>
    <axis xyz="1 0 0"/>
    <parent link="front_left_wheel_link"/>
    <child link="front_left_roller7_link"/>
    <dynamics damping="0.001" friction="0.0001"/>
  </joint>
  <transmission name="${name}_roller7_trans">
    <type>transmission_interface/SimpleTransmission</type>
    <joint name="front_left_roller7_joint">
      <hardwareInterface>hardware_interface/EffortJointInterface</hardwareInterface>
    </joint>
    <actuator name="front_left_roller7_motor">
      <hardwareInterface>hardware_interface/EffortJointInterface</hardwareInterface>
      <mechanismReduction>1</mechanismReduction>
    </actuator>
  </transmission>
  <gazebo reference="front_left_roller7_link">
    <mu1 value="0.8"/>
    <mu2 value="0.8"/>
    <kp value="10000000.0"/>
    <kd value="1.0"/>
    <fdir1 value="0 1 0"/>
  </gazebo>
  <link name="front_left_roller6_link">
    <visual>
      <origin rpy="0 0 0" xyz="0 0 0"/>
      <geometry>
        <mesh filename="package://mesh/visual/roller.dae" scale="1 1 1"/>
      </geometry>
    </visual>
    <collision>
      <geometry>
        <mesh filename="package://mesh/collision/roller.stl" scale="1 1 1"/>
      </geometry>
    </collision>
    <inertial>
      <origin xyz="0 0 0"/>
      <mass value="0.3"/>
      <inertia ixx="0.00024000" ixy="0.0" ixz="0.0" iyy="0.00076000" iyz="0.0" izz="0.00076000"/>
    </inertial>
  </link>
  <joint name="front_left_roller6_joint" type="continuous">
    <origin rpy="1.1831996401397162 0.3613671239067076 -0.7137243789447657" xyz="0 -0.04474999999999998 0.07750927363870726"/>
    <axis xyz="1 0 0"/>
    <parent link="front_left_wheel_link"/>
    <child link="front_left_roller6_link"/>
    <dynamics damping="0.001" friction="0.0001"/>
  </joint>
  <transmission name="${name}_roller6_trans">
    <type>transmission_interface/SimpleTransmission</type>
    <joint name="front_left_roller6_joint">
      <hardwareInterface>hardware_interface/EffortJointInterface</hardwareInterface>
    </joint>
    <actuator name="front_left_roller6_motor">
      <hardwareInterface>hardware_interface/EffortJointInterface</hardwareInterface>
      <mechanismReduction>1</mechanismReduction>
    </actuator>
  </transmission>
  <gazebo reference="front_left_roller6_link">
    <mu1 value="0.8"/>
    <mu2 value="0.8"/>
    <kp value="10000000.0"/>
    <kd value="1.0"/>
    <fdir1 value="0 1 0"/>
  </gazebo>
  <link name="front_left_roller5_link">
    <visual>
      <origin rpy="0 0 0" xyz="0 0 0"/>
      <geometry>
        <mesh filename="package://mesh/visual/roller.dae" scale="1 1 1"/>
      </geometry>
    </visual>
    <collision>
      <geometry>
        <mesh filename="package://mesh/collision/roller.stl" scale="1 1 1"/>
      </geometry>
    </collision>
    <inertial>
      <origin xyz="0 0 0"/>
      <mass value="0.3"/>
      <inertia ixx="0.00024000" ixy="0.0" ixz="0.0" iyy="0.00076000" iyz="0.0" izz="0.00076000"/>
    </inertial>
  </link>
  <joint name="front_left_roller5_joint" type="continuous">
    <origin rpy="1.4966127917301504 0.07398025001120949 -0.7826515949744619" xyz="0 -0.009355297462454993 0.08900970963546045"/>
    <axis xyz="1 0 0"/>
    <parent link="front_left_wheel_link"/>
    <child link="front_left_roller5_link"/>
    <dynamics damping="0.001" friction="0.0001"/>
  </joint>
  <transmission name="${name}_roller5_trans">
    <type>transmission_interface/SimpleTransmission</type>
    <joint name="front_left_roller5_joint">
      <hardwareInterface>hardware_interface/EffortJointInterface</hardwareInterface>
    </joint>
    <actuator name="front_left_roller5_motor">
      <hardwareInterface>hardware_interface/EffortJointInterface</hardwareInterface>
      <mechanismReduction>1</mechanismReduction>
    </actuator>
  </transmission>
  <gazebo reference="front_left_roller5_link">
    <mu1 value="0.8"/>
    <mu2 value="0.8"/>
    <kp value="10000000.0"/>
    <kd value="1.0"/>
    <fdir1 value="0 1 0"/>
  </gazebo>
  <link name="front_left_roller4_link">
    <visual>
      <origin rpy="0 0 0" xyz="0 0 0"/>
      <geometry>
        <mesh filename="package://mesh/visual/roller.dae" scale="1 1 1"/>
      </geometry>
    </visual>
    <collision>
      <geometry>
        <mesh filename="package://mesh/collision/roller.stl" scale="1 1 1"/>
      </geometry>
    </collision>
    <inertial>
      <origin xyz="0 0 0"/>
      <mass value="0.3"/>
      <inertia ixx="0.00024000" ixy="0.0" ixz="0.0" iyy="0.00076000" iyz="0.0" izz="0.00076000"/>
    </inertial>
  </link>
  <joint name="front_left_roller4_joint" type="continuous">
    <origin rpy="-1.3449626171032882 -0.2202852738547472 -0.7603177925108144" xyz="0 0.027657020996557796 0.08511955820841624"/>
    <axis xyz="1 0 0"/>
    <parent link="front_left_wheel_link"/>
    <child link="front_left_roller4_link"/>
    <dynamics damping="0.001" friction="0.0001"/>
  </joint>
  <transmission name="${name}_roller4_trans">
    <type>transmission_interface/SimpleTransmission</type>
    <joint name="front_left_roller4_joint">
      <hardwareInterface>hardware_interface/EffortJointInterface</hardwareInterface>
    </joint>
    <actuator name="front_left_roller4_motor">
      <hardwareInterface>hardware_interface/EffortJointInterface</hardwareInterface>
      <mechanismReduction>1</mechanismReduction>
    </actuator>
  </transmission>
  <gazebo reference="front_left_roller4_link">
    <mu1 value="0.8"/>
    <mu2 value="0.8"/>
    <kp value="10000000.0"/>
    <kd value="1.0"/>
    <fdir1 value="0 1 0"/>
  </gazebo>
  <link name="front_left_roller3_link">
    <visual>
      <origin rpy="0 0 0" xyz="0 0 0"/>
      <geometry>
        <mesh filename="package://mesh/visual/roller.dae" scale="1 1 1"/>
      </geometry>
    </visual>
    <collision>
      <geometry>
        <mesh filename="package://mesh/collision/roller.stl" scale="1 1 1"/>
      </geometry>
    </collision>
    <inertial>
      <origin xyz="0 0 0"/>
      <mass value="0.3"/>
      <inertia ixx="0.00024000" ixy="0.0" ixz="0.0" iyy="0.00076000" iyz="0.0" izz="0.00076000"/>
    </inertial>
  </link>
  <joint name="front_left_roller3_joint" type="continuous">
    <origin rpy="-1.0038406803226867 -0.4928592704898485 -0.6390993414905141" xyz="0 0.05988718926911781 0.06651146188022679"/>
    <axis xyz="1 0 0"/>
    <parent link="front_left_wheel_link"/>
    <child link="front_left_roller3_link"/>
    <dynamics damping="0.001" friction="0.0001"/>
  </joint>
  <transmission name="${name}_roller3_trans">
    <type>transmission_interface/SimpleTransmission</type>
    <joint name="front_left_roller3_joint">
      <hardwareInterface>hardware_interface/EffortJointInterface</hardwareInterface>
    </joint>
    <actuator name="front_left_roller3_motor">
      <hardwareInterface>hardware_interface/EffortJointInterface</hardwareInterface>
      <mechanismReduction>1</mechanismReduction>
    </actuator>
  </transmission>
  <gazebo reference="front_left_roller3_link">
    <mu1 value="0.8"/>
    <mu2 value="0.8"/>
    <kp value="10000000.0"/>
    <kd value="1.0"/>
    <fdir1 value="0 1 0"/>
  </gazebo>
  <link name="front_left_roller2_link">
    <visual>
      <origin rpy="0 0 0" xyz="0 0 0"/>
      <geometry>
        <mesh filename="package://mesh/visual/roller.dae" scale="1 1 1"/>
      </geometry>
    </visual>
    <collision>
      <geometry>
        <mesh filename="package://mesh/collision/roller.stl" scale="1 1 1"/>
      </geometry>
    </collision>
    <inertial>
      <origin xyz="0 0 0"/>
      <mass value="0.3"/>
      <inertia ixx="0.00024000" ixy="0.0" ixz="0.0" iyy="0.00076000" iyz="0.0" izz="0.00076000"/>
    </inertial>
  </link>
  <joint name="front_left_roller2_joint" type="continuous">
    <origin rpy="-0.5619350361043128 -0.702298780729168 -0.3863003038769115" xyz="0 0.08176231845901277 0.03640292955528412"/>
    <axis xyz="1 0 0"/>
    <parent link="front_left_wheel_link"/>
    <child link="front_left_roller2_link"/>
    <dynamics damping="0.001" friction="0.0001"/>
  </joint>
  <transmission name="${name}_roller2_trans">
    <type>transmission_interface/SimpleTransmission</type>
    <joint name="front_left_roller2_joint">
      <hardwareInterface>hardware_interface/EffortJointInterface</hardwareInterface>
    </joint>
    <actuator name="front_left_roller2_motor">
      <hardwareInterface>hardware_interface/EffortJointInterface</hardwareInterface>
      <mechanismReduction>1</mechanismReduction>
    </actuator>
  </transmission>
  <gazebo reference="front_left_roller2_link">
    <mu1 value="0.8"/>
    <mu2 value="0.8"/>
    <kp value="10000000.0"/>
    <kd value="1.0"/>
    <fdir1 value="0 1 0"/>
  </gazebo>
  <link name="front_left_roller1_link">
    <visual>
      <origin rpy="0 0 0" xyz="0 0 0"/>
      <geometry>
        <mesh filename="package://mesh/visual/roller.dae" scale="1 1 1"/>
      </geometry>
    </visual>
    <collision>
      <geometry>
        <mesh filename="package://mesh/collision/roller.stl" scale="1 1 1"/>
      </geometry>
    </collision>
    <inertial>
      <origin xyz="0 0 0"/>
      <mass value="0.3"/>
      <inertia ixx="0.00024000" ixy="0.0" ixz="0.0" iyy="0.00076000" iyz="0.0" izz="0.00076000"/>
    </inertial>
  </link>
  <joint name="front_left_roller1_joint" type="continuous">
    <origin rpy="-0.0 -0.7853981633974482 -0.0" xyz="0 0.0895 0.0"/>
    <axis xyz="1 0 0"/>
    <parent link="front_left_wheel_link"/>
    <child link="front_left_roller1_link"/>
    <dynamics damping="0.001" friction="0.0001"/>
  </joint>
  <transmission name="${name}_roller1_trans">
    <type>transmission_interface/SimpleTransmission</type>
    <joint name="front_left_roller1_joint">
      <hardwareInterface>hardware_interface/EffortJointInterface</hardwareInterface>
    </joint>
    <actuator name="front_left_roller1_motor">
      <hardwareInterface>hardware_interface/EffortJointInterface</hardwareInterface>
      <mechanismReduction>1</mechanismReduction>
    </actuator>
  </transmission>
  <gazebo reference="front_left_roller1_link">
    <mu1 value="0.8"/>
    <mu2 value="0.8"/>
    <kp value="10000000.0"/>
    <kd value="1.0"/>
    <fdir1 value="0 1 0"/>
  </gazebo>
  <transmission name="front_left_wheel_trans">
    <type>transmission_interface/SimpleTransmission</type>
    <joint name="front_left_wheel_joint">
      <hardwareInterface>hardware_interface/EffortJointInterface</hardwareInterface>
    </joint>
    <actuator name="front_left_wheel_motor">
      <hardwareInterface>hardware_interface/EffortJointInterface</hardwareInterface>
      <mechanismReduction>1</mechanismReduction>
    </actuator>
  </transmission>
  <link name="rear_right_wheel_link">
    <visual>
      <origin rpy="0 0 0" xyz="0 0 0"/>
      <geometry>
        <mesh filename="package://mesh/visual/wheel.dae" scale="-1 1 1"/>
      </geometry>
    </visual>
    <collision>
      <geometry>
        <mesh filename="package://mesh/collision/wheel.stl" scale="-1 1 1"/>
      </geometry>
    </collision>
    <inertial>
      <origin xyz="0 0 0"/>
      <mass value="2.0"/>
      <inertia ixx="0.042025" ixy="0.0" ixz="0.0" iyy="0.024279" iyz="0.0" izz="0.024279"/>
    </inertial>
  </link>
  <gazebo reference="rear_right_wheel_link">
    <mu1 value="0.6"/>
    <mu2 value="0.6"/>
    <kp value="10000000.0"/>
    <kd value="1.0"/>
    <fdir1 value="0 1 0"/>
  </gazebo>
  <link name="rear_right_roller15_link">
    <visual>
      <origin rpy="0 0 0" xyz="0 0 0"/>
      <geometry>
        <mesh filename="package://mesh/visual/roller.dae" scale="1 1 1"/>
      </geometry>
    </visual>
    <collision>
      <geometry>
        <mesh filename="package://mesh/collision/roller.stl" scale="1 1 1"/>
      </geometry>
    </collision>
    <inertial>
      <origin xyz="0 0 0"/>
      <mass value="0.3"/>
      <inertia ixx="0.00024000" ixy="0.0" ixz="0.0" iyy="0.00076000" iyz="0.0" izz="0.00076000"/>
    </inertial>
  </link>
  <joint name="rear_right_roller15_joint" type="continuous">
    <origin rpy="0.5619350361043127 -0.7022987807291682 0.38630030387691144" xyz="0 0.08176231845901279 -0.03640292955528411"/>
    <axis xyz="1 0 0"/>
    <parent link="rear_right_wheel_link"/>
    <child link="rear_right_roller15_link"/>
    <dynamics damping="0.001" friction="0.0001"/>
  </joint>
  <transmission name="${name}_roller15_trans">
    <type>transmission_interface/SimpleTransmission</type>
    <joint name="rear_right_roller15_joint">
      <hardwareInterface>hardware_interface/EffortJointInterface</hardwareInterface>
    </joint>
    <actuator name="rear_right_roller15_motor">
      <hardwareInterface>hardware_interface/EffortJointInterface</hardwareInterface>
      <mechanismReduction>1</mechanismReduction>
    </actuator>
  </transmission>
  <gazebo reference="rear_right_roller15_link">
    <mu1 value="0.8"/>
    <mu2 value="0.8"/>
    <kp value="10000000.0"/>
    <kd value="1.0"/>
    <fdir1 value="0 1 0"/>
  </gazebo>
  <link name="rear_right_roller14_link">
    <visual>
      <origin rpy="0 0 0" xyz="0 0 0"/>
      <geometry>
        <mesh filename="package://mesh/visual/roller.dae" scale="1 1 1"/>
      </geometry>
    </visual>
    <collision>
      <geometry>
        <mesh filename="package://mesh/collision/roller.stl" scale="1 1 1"/>
      </geometry>
    </collision>
    <inertial>
      <origin xyz="0 0 0"/>
      <mass value="0.3"/>
      <inertia ixx="0.00024000" ixy="0.0" ixz="0.0" iyy="0.00076000" iyz="0.0" izz="0.00076000"/>
    </inertial>
  </link>
  <joint name="rear_right_roller14_joint" type="continuous">
    <origin rpy="1.0038406803226874 -0.4928592704898482 0.6390993414905143" xyz="0 0.05988718926911777 -0.06651146188022682"/>
    <axis xyz="1 0 0"/>
    <parent link="rear_right_wheel_link"/>
    <child link="rear_right_roller14_link"/>
    <dynamics damping="0.001" friction="0.0001"/>
  </joint>
  <transmission name="${name}_roller14_trans">
    <type>transmission_interface/SimpleTransmission</type>
    <joint name="rear_right_roller14_joint">
      <hardwareInterface>hardware_interface/EffortJointInterface</hardwareInterface>
    </joint>
    <actuator name="rear_right_roller14_motor">
      <hardwareInterface>hardware_interface/EffortJointInterface</hardwareInterface>
      <mechanismReduction>1</mechanismReduction>
    </actuator>
  </transmission>
  <gazebo reference="rear_right_roller14_link">
    <mu1 value="0.8"/>
    <mu2 value="0.8"/>
    <kp value="10000000.0"/>
    <kd value="1.0"/>
    <fdir1 value="0 1 0"/>
  </gazebo>
  <link name="rear_right_roller13_link">
    <visual>
      <origin rpy="0 0 0" xyz="0 0 0"/>
      <geometry>
        <mesh filename="package://mesh/visual/roller.dae" scale="1 1 1"/>
      </geometry>
    </visual>
    <collision>
      <geometry>
        <mesh filename="package://mesh/collision/roller.stl" scale="1 1 1"/>
      </geometry>
    </collision>
    <inertial>
      <origin xyz="0 0 0"/>
      <mass value="0.3"/>
      <inertia ixx="0.00024000" ixy="0.0" ixz="0.0" iyy="0.00076000" iyz="0.0" izz="0.00076000"/>
    </inertial>
  </link>
  <joint name="rear_right_roller13_joint" type="continuous">
    <origin rpy="1.3449626171032882 -0.22028527385474703 0.7603177925108144" xyz="0 0.027657020996557775 -0.08511955820841624"/>
    <axis xyz="1 0 0"/>
    <parent link="rear_right_wheel_link"/>
    <child link="rear_right_roller13_link"/>
    <dynamics damping="0.001" friction="0.0001"/>
  </joint>
  <transmission name="${name}_roller13_trans">
    <type>transmission_interface/SimpleTransmission</type>
    <joint name="rear_right_roller13_joint">
      <hardwareInterface>hardware_interface/EffortJointInterface</hardwareInterface>
    </joint>
    <actuator name="rear_right_roller13_motor">
      <hardwareInterface>hardware_interface/EffortJointInterface</hardwareInterface>
      <mechanismReduction>1</mechanismReduction>
    </actuator>
  </transmission>
  <gazebo reference="rear_right_roller13_link">
    <mu1 value="0.8"/>
    <mu2 value="0.8"/>
    <kp value="10000000.0"/>
    <kd value="1.0"/>
    <fdir1 value="0 1 0"/>
  </gazebo>
  <link name="rear_right_roller12_link">
    <visual>
      <origin rpy="0 0 0" xyz="0 0 0"/>
      <geometry>
        <mesh filename="package://mesh/visual/roller.dae" scale="1 1 1"/>
      </geometry>
    </visual>
    <collision>
      <geometry>
        <mesh filename="package://mesh/collision/roller.stl" scale="1 1 1"/>
      </geometry>
    </collision>
    <inertial>
      <origin xyz="0 0 0"/>
      <mass value="0.3"/>
      <inertia ixx="0.00024000" ixy="0.0" ixz="0.0" iyy="0.00076000" iyz="0.0" izz="0.00076000"/>
    </inertial>
  </link>
  <joint name="rear_right_roller12_joint" type="continuous">
    <origin rpy="-1.4966127917301506 0.07398025001120935 0.7826515949744619" xyz="0 -0.009355297462454976 -0.08900970963546047"/>
    <axis xyz="1 0 0"/>
    <parent link="rear_right_wheel_link"/>
    <child link="rear_right_roller12_link"/>
    <dynamics damping="0.001" friction="0.0001"/>
  </joint>
  <transmission name="${name}_roller12_trans">
    <type>transmission_interface/SimpleTransmission</type>
    <joint name="rear_right_roller12_joint">
      <hardwareInterface>hardware_interface/EffortJointInterface</hardwareInterface>
    </joint>
    <actuator name="rear_right_roller12_motor">
      <hardwareInterface>hardware_interface/EffortJointInterface</hardwareInterface>
      <mechanismReduction>1</mechanismReduction>
    </actuator>
  </transmission>
  <gazebo reference="rear_right_roller12_link">
    <mu1 value="0.8"/>
    <mu2 value="0.8"/>
    <kp value="10000000.0"/>
    <kd value="1.0"/>
    <fdir1 value="0 1 0"/>
  </gazebo>
  <link name="rear_right_roller11_link">
    <visual>
      <origin rpy="0 0 0" xyz="0 0 0"/>
      <geometry>
        <mesh filename="package://mesh/visual/roller.dae" scale="1 1 1"/>
      </geometry>
    </visual>
    <collision>
      <geometry>
        <mesh filename="package://mesh/collision/roller.stl" scale="1 1 1"/>
      </geometry>
    </collision>
    <inertial>
      <origin xyz="0 0 0"/>
      <mass value="0.3"/>
      <inertia ixx="0.00024000" ixy="0.0" ixz="0.0" iyy="0.00076000" iyz="0.0" izz="0.00076000"/>
    </inertial>
  </link>
  <joint name="rear_right_roller11_joint" type="continuous">
    <origin rpy="-1.1831996401397156 0.3613671239067081 0.7137243789447655" xyz="0 -0.04475000000000004 -0.07750927363870723"/>
    <axis xyz="1 0 0"/>
    <parent link="rear_right_wheel_link"/>
    <child link="rear_right_roller11_link"/>
    <dynamics damping="0.001" friction="0.0001"/>
  </joint>
  <transmission name="${name}_roller11_trans">
    <type>transmission_interface/SimpleTransmission</type>
    <joint name="rear_right_roller11_joint">
      <hardwareInterface>hardware_interface/EffortJointInterface</hardwareInterface>
    </joint>
    <actuator name="rear_right_roller11_motor">
      <hardwareInterface>hardware_interface/EffortJointInterface</hardwareInterface>
      <mechanismReduction>1</mechanismReduction>
    </actuator>
  </transmission>
  <gazebo reference="rear_right_roller11_link">
    <mu1 value="0.8"/>
    <mu2 value="0.8"/>
    <kp value="10000000.0"/>
    <kd value="1.0"/>
    <fdir1 value="0 1 0"/>
  </gazebo>
  <link name="rear_right_roller10_link">
    <visual>
      <origin rpy="0 0 0" xyz="0 0 0"/>
      <geometry>
        <mesh filename="package://mesh/visual/roller.dae" scale="1 1 1"/>
      </geometry>
    </visual>
    <collision>
      <geometry>
        <mesh filename="package://mesh/collision/roller.stl" scale="1 1 1"/>
      </geometry>
    </collision>
    <inertial>
      <origin xyz="0 0 0"/>
      <mass value="0.3"/>
      <inertia ixx="0.00024000" ixy="0.0" ixz="0.0" iyy="0.00076000" iyz="0.0" izz="0.00076000"/>
    </inertial>
  </link>
  <joint name="rear_right_roller10_joint" type="continuous">
    <origin rpy="-0.7989541677433551 0.6090169187607924 0.5313896516603533" xyz="0 -0.0724070209965578 -0.05260678008017634"/>
    <axis xyz="1 0 0"/>
    <parent link="rear_right_wheel_link"/>
    <child link="rear_right_roller10_link"/>
    <dynamics damping="0.001" friction="0.0001"/>
  </joint>
  <transmission name="${name}_roller10_trans">
    <type>transmission_interface/SimpleTransmission</type>
    <joint name="rear_right_roller10_joint">
      <hardwareInterface>hardware_interface/EffortJointInterface</hardwareInterface>
    </joint>
    <actuator name="rear_right_roller10_motor">
      <hardwareInterface>hardware_interface/EffortJointInterface</hardwareInterface>
      <mechanismReduction>1</mechanismReduction>
    </actuator>
  </transmission>
  <gazebo reference="rear_right_roller10_link">
    <mu1 value="0.8"/>
    <mu2 value="0.8"/>
    <kp value="10000000.0"/>
    <kd value="1.0"/>
    <fdir1 value="0 1 0"/>
  </gazebo>
  <link name="rear_right_roller9_link">
    <visual>
      <origin rpy="0 0 0" xyz="0 0 0"/>
      <geometry>
        <mesh filename="package://mesh/visual/roller.dae" scale="1 1 1"/>
      </geometry>
    </visual>
    <collision>
      <geometry>
        <mesh filename="package://mesh/collision/roller.stl" scale="1 1 1"/>
      </geometry>
    </collision>
    <inertial>
      <origin xyz="0 0 0"/>
      <mass value="0.3"/>
      <inertia ixx="0.00024000" ixy="0.0" ixz="0.0" iyy="0.00076000" iyz="0.0" izz="0.00076000"/>
    </inertial>
  </link>
  <joint name="rear_right_roller9_joint" type="continuous">
    <origin rpy="-0.29200750368454736 0.7637777909460687 0.20499125187874406" xyz="0 -0.08754421026567559 -0.018608096328189477"/>
    <axis xyz="1 0 0"/>
    <parent link="rear_right_wheel_link"/>
    <child link="rear_right_roller9_link"/>
    <dynamics damping="0.001" friction="0.0001"/>
  </joint>
  <transmission name="${name}_roller9_trans">
    <type>transmission_interface/SimpleTransmission</type>
    <joint name="rear_right_roller9_joint">
      <hardwareInterface>hardware_interface/EffortJointInterface</hardwareInterface>
    </joint>
    <actuator name="rear_right_roller9_motor">
      <hardwareInterface>hardware_interface/EffortJointInterface</hardwareInterface>
      <mechanismReduction>1</mechanismReduction>
    </actuator>
  </transmission>
  <gazebo reference="rear_right_roller9_link">
    <mu1 value="0.8"/>
    <mu2 value="0.8"/>
    <kp value="10000000.0"/>
    <kd value="1.0"/>
    <fdir1 value="0 1 0"/>
  </gazebo>
  <link name="rear_right_roller8_link">
    <visual>
      <origin rpy="0 0 0" xyz="0 0 0"/>
      <geometry>
        <mesh filename="package://mesh/visual/roller.dae" scale="1 1 1"/>
      </geometry>
    </visual>
    <collision>
      <geometry>
        <mesh filename="package://mesh/collision/roller.stl" scale="1 1 1"/>
      </geometry>
    </collision>
    <inertial>
      <origin xyz="0 0 0"/>
      <mass value="0.3"/>
      <inertia ixx="0.00024000" ixy="0.0" ixz="0.0" iyy="0.00076000" iyz="0.0" izz="0.00076000"/>
    </inertial>
  </link>
  <joint name="rear_right_roller8_joint" type="continuous">
    <origin rpy="0.2920075036845471 0.7637777909460687 -0.20499125187874387" xyz="0 -0.0875442102656756 0.01860809632818946"/>
    <axis xyz="1 0 0"/>
    <parent link="rear_right_wheel_link"/>
    <child link="rear_right_roller8_link"/>
    <dynamics damping="0.001" friction="0.0001"/>
  </joint>
  <transmission name="${name}_roller8_trans">
    <type>transmission_interface/SimpleTransmission</type>
    <joint name="rear_right_roller8_joint">
      <hardwareInterface>hardware_interface/EffortJointInterface</hardwareInterface>
    </joint>
    <actuator name="rear_right_roller8_motor">
      <hardwareInterface>hardware_interface/EffortJointInterface</hardwareInterface>
      <mechanismReduction>1</mechanismReduction>
    </actuator>
  </transmission>
  <gazebo reference="rear_right_roller8_link">
    <mu1 value="0.8"/>
    <mu2 value="0.8"/>
    <kp value="10000000.0"/>
    <kd value="1.0"/>
    <fdir1 value="0 1 0"/>
  </gazebo>
  <link name="rear_right_roller7_link">
    <visual>
      <origin rpy="0 0 0" xyz="0 0 0"/>
      <geometry>
        <mesh filename="package://mesh/visual/roller.dae" scale="1 1 1"/>
      </geometry>
    </visual>
    <collision>
      <geometry>
        <mesh filename="package://mesh/collision/roller.stl" scale="1 1 1"/>
      </geometry>
    </collision>
    <inertial>
      <origin xyz="0 0 0"/>
      <mass value="0.3"/>
      <inertia ixx="0.00024000" ixy="0.0" ixz="0.0" iyy="0.00076000" iyz="0.0" izz="0.00076000"/>
    </inertial>
  </link>
  <joint name="rear_right_roller7_joint" type="continuous">
    <origin rpy="0.7989541677433554 0.6090169187607923 -0.5313896516603536" xyz="0 -0.07240702099655778 0.05260678008017635"/>
    <axis xyz="1 0 0"/>
    <parent link="rear_right_wheel_link"/>
    <child link="rear_right_roller7_link"/>
    <dynamics damping="0.001" friction="0.0001"/>
  </joint>
  <transmission name="${name}_roller7_trans">
    <type>transmission_interface/SimpleTransmission</type>
    <joint name="rear_right_roller7_joint">
      <hardwareInterface>hardware_interface/EffortJointInterface</hardwareInterface>
    </joint>
    <actuator name="rear_right_roller7_motor">
      <hardwareInterface>hardware_interface/EffortJointInterface</hardwareInterface>
      <mechanismReduction>1</mechanismReduction>
    </actuator>
  </transmission>
  <gazebo reference="rear_right_roller7_link">
    <mu1 value="0.8"/>
    <mu2 value="0.8"/>
    <kp value="10000000.0"/>
    <kd value="1.0"/>
    <fdir1 value="0 1 0"/>
  </gazebo>
  <link name="rear_right_roller6_link">
    <visual>
      <origin rpy="0 0 0" xyz="0 0 0"/>
      <geometry>
        <mesh filename="package://mesh/visual/roller.dae" scale="1 1 1"/>
      </geometry>
    </visual>
    <collision>
      <geometry>
        <mesh filename="package://mesh/collision/roller.stl" scale="1 1 1"/>
      </geometry>
    </collision>
    <inertial>
      <origin xyz="0 0 0"/>
      <mass value="0.3"/>
      <inertia ixx="0.00024000" ixy="0.0" ixz="0.0" iyy="0.00076000" iyz="0.0" izz="0.00076000"/>
    </inertial>
  </link>
  <joint name="rear_right_roller6_joint" type="continuous">
    <origin rpy="1.1831996401397162 0.3613671239067076 -0.7137243789447657" xyz="0 -0.04474999999999998 0.07750927363870726"/>
    <axis xyz="1 0 0"/>
    <parent link="rear_right_wheel_link"/>
    <child link="rear_right_roller6_link"/>
    <dynamics damping="0.001" friction="0.0001"/>
  </joint>
  <transmission name="${name}_roller6_trans">
    <type>transmission_interface/SimpleTransmission</type>
    <joint name="rear_right_roller6_joint">
      <hardwareInterface>hardware_interface/EffortJointInterface</hardwareInterface>
    </joint>
    <actuator name="rear_right_roller6_motor">
      <hardwareInterface>hardware_interface/EffortJointInterface</hardwareInterface>
      <mechanismReduction>1</mechanismReduction>
    </actuator>
  </transmission>
  <gazebo reference="rear_right_roller6_link">
    <mu1 value="0.8"/>
    <mu2 value="0.8"/>
    <kp value="10000000.0"/>
    <kd value="1.0"/>
    <fdir1 value="0 1 0"/>
  </gazebo>
  <link name="rear_right_roller5_link">
    <visual>
      <origin rpy="0 0 0" xyz="0 0 0"/>
      <geometry>
        <mesh filename="package://mesh/visual/roller.dae" scale="1 1 1"/>
      </geometry>
    </visual>
    <collision>
      <geometry>
        <mesh filename="package://mesh/collision/roller.stl" scale="1 1 1"/>
      </geometry>
    </collision>
    <inertial>
      <origin xyz="0 0 0"/>
      <mass value="0.3"/>
      <inertia ixx="0.00024000" ixy="0.0" ixz="0.0" iyy="0.00076000" iyz="0.0" izz="0.00076000"/>
    </inertial>
  </link>
  <joint name="rear_right_roller5_joint" type="continuous">
    <origin rpy="1.4966127917301504 0.07398025001120949 -0.7826515949744619" xyz="0 -0.009355297462454993 0.08900970963546045"/>
    <axis xyz="1 0 0"/>
    <parent link="rear_right_wheel_link"/>
    <child link="rear_right_roller5_link"/>
    <dynamics damping="0.001" friction="0.0001"/>
  </joint>
  <transmission name="${name}_roller5_trans">
    <type>transmission_interface/SimpleTransmission</type>
    <joint name="rear_right_roller5_joint">
      <hardwareInterface>hardware_interface/EffortJointInterface</hardwareInterface>
    </joint>
    <actuator name="rear_right_roller5_motor">
      <hardwareInterface>hardware_interface/EffortJointInterface</hardwareInterface>
      <mechanismReduction>1</mechanismReduction>
    </actuator>
  </transmission>
  <gazebo reference="rear_right_roller5_link">
    <mu1 value="0.8"/>
    <mu2 value="0.8"/>
    <kp value="10000000.0"/>
    <kd value="1.0"/>
    <fdir1 value="0 1 0"/>
  </gazebo>
  <link name="rear_right_roller4_link">
    <visual>
      <origin rpy="0 0 0" xyz="0 0 0"/>
      <geometry>
        <mesh filename="package://mesh/visual/roller.dae" scale="1 1 1"/>
      </geometry>
    </visual>
    <collision>
      <geometry>
        <mesh filename="package://mesh/collision/roller.stl" scale="1 1 1"/>
      </geometry>
    </collision>
    <inertial>
      <origin xyz="0 0 0"/>
      <mass value="0.3"/>
      <inertia ixx="0.00024000" ixy="0.0" ixz="0.0" iyy="0.00076000" iyz="0.0" izz="0.00076000"/>
    </inertial>
  </link>
  <joint name="rear_right_roller4_joint" type="continuous">
    <origin rpy="-1.3449626171032882 -0.2202852738547472 -0.7603177925108144" xyz="0 0.027657020996557796 0.08511955820841624"/>
    <axis xyz="1 0 0"/>
    <parent link="rear_right_wheel_link"/>
    <child link="rear_right_roller4_link"/>
    <dynamics damping="0.001" friction="0.0001"/>
  </joint>
  <transmission name="${name}_roller4_trans">
    <type>transmission_interface/SimpleTransmission</type>
    <joint name="rear_right_roller4_joint">
      <hardwareInterface>hardware_interface/EffortJointInterface</hardwareInterface>
    </joint>
    <actuator name="rear_right_roller4_motor">
      <hardwareInterface>hardware_interface/EffortJointInterface</hardwareInterface>
      <mechanismReduction>1</mechanismReduction>
    </actuator>
  </transmission>
  <gazebo reference="rear_right_roller4_link">
    <mu1 value="0.8"/>
    <mu2 value="0.8"/>
    <kp value="10000000.0"/>
    <kd value="1.0"/>
    <fdir1 value="0 1 0"/>
  </gazebo>
  <link name="rear_right_roller3_link">
    <visual>
      <origin rpy="0 0 0" xyz="0 0 0"/>
      <geometry>
        <mesh filename="package://mesh/visual/roller.dae" scale="1 1 1"/>
      </geometry>
    </visual>
    <collision>
      <geometry>
        <mesh filename="package://mesh/collision/roller.stl" scale="1 1 1"/>
      </geometry>
    </collision>
    <inertial>
      <origin xyz="0 0 0"/>
      <mass value="0.3"/>
      <inertia ixx="0.00024000" ixy="0.0" ixz="0.0" iyy="0.00076000" iyz="0.0" izz="0.00076000"/>
    </inertial>
  </link>
  <joint name="rear_right_roller3_joint" type="continuous">
    <origin rpy="-1.0038406803226867 -0.4928592704898485 -0.6390993414905141" xyz="0 0.05988718926911781 0.06651146188022679"/>
    <axis xyz="1 0 0"/>
    <parent link="rear_right_wheel_link"/>
    <child link="rear_right_roller3_link"/>
    <dynamics damping="0.001" friction="0.0001"/>
  </joint>
  <transmission name="${name}_roller3_trans">
    <type>transmission_interface/SimpleTransmission</type>
    <joint name="rear_right_roller3_joint">
      <hardwareInterface>hardware_interface/EffortJointInterface</hardwareInterface>
    </joint>
    <actuator name="rear_right_roller3_motor">
      <hardwareInterface>hardware_interface/EffortJointInterface</hardwareInterface>
      <mechanismReduction>1</mechanismReduction>
    </actuator>
  </transmission>
  <gazebo reference="rear_right_roller3_link">
    <mu1 value="0.8"/>
    <mu2 value="0.8"/>
    <kp value="10000000.0"/>
    <kd value="1.0"/>
    <fdir1 value="0 1 0"/>
  </gazebo>
  <link name="rear_right_roller2_link">
    <visual>
      <origin rpy="0 0 0" xyz="0 0 0"/>
      <geometry>
        <mesh filename="package://mesh/visual/roller.dae" scale="1 1 1"/>
      </geometry>
    </visual>
    <collision>
      <geometry>
        <mesh filename="package://mesh/collision/roller.stl" scale="1 1 1"/>
      </geometry>
    </collision>
    <inertial>
      <origin xyz="0 0 0"/>
      <mass value="0.3"/>
      <inertia ixx="0.00024000" ixy="0.0" ixz="0.0" iyy="0.00076000" iyz="0.0" izz="0.00076000"/>
    </inertial>
  </link>
  <joint name="rear_right_roller2_joint" type="continuous">
    <origin rpy="-0.5619350361043128 -0.702298780729168 -0.3863003038769115" xyz="0 0.08176231845901277 0.03640292955528412"/>
    <axis xyz="1 0 0"/>
    <parent link="rear_right_wheel_link"/>
    <child link="rear_right_roller2_link"/>
    <dynamics damping="0.001" friction="0.0001"/>
  </joint>
  <transmission name="${name}_roller2_trans">
    <type>transmission_interface/SimpleTransmission</type>
    <joint name="rear_right_roller2_joint">
      <hardwareInterface>hardware_interface/EffortJointInterface</hardwareInterface>
    </joint>
    <actuator name="rear_right_roller2_motor">
      <hardwareInterface>hardware_interface/EffortJointInterface</hardwareInterface>
      <mechanismReduction>1</mechanismReduction>
    </actuator>
  </transmission>
  <gazebo reference="rear_right_roller2_link">
    <mu1 value="0.8"/>
    <mu2 value="0.8"/>
    <kp value="10000000.0"/>
    <kd value="1.0"/>
    <fdir1 value="0 1 0"/>
  </gazebo>
  <link name="rear_right_roller1_link">
    <visual>
      <origin rpy="0 0 0" xyz="0 0 0"/>
      <geometry>
        <mesh filename="package://mesh/visual/roller.dae" scale="1 1 1"/>
      </geometry>
    </visual>
    <collision>
      <geometry>
        <mesh filename="package://mesh/collision/roller.stl" scale="1 1 1"/>
      </geometry>
    </collision>
    <inertial>
      <origin xyz="0 0 0"/>
      <mass value="0.3"/>
      <inertia ixx="0.00024000" ixy="0.0" ixz="0.0" iyy="0.00076000" iyz="0.0" izz="0.00076000"/>
    </inertial>
  </link>
  <joint name="rear_right_roller1_joint" type="continuous">
    <origin rpy="-0.0 -0.7853981633974482 -0.0" xyz="0 0.0895 0.0"/>
    <axis xyz="1 0 0"/>
    <parent link="rear_right_wheel_link"/>
    <child link="rear_right_roller1_link"/>
    <dynamics damping="0.001" friction="0.0001"/>
  </joint>
  <transmission name="${name}_roller1_trans">
    <type>transmission_interface/SimpleTransmission</type>
    <joint name="rear_right_roller1_joint">
      <hardwareInterface>hardware_interface/EffortJointInterface</hardwareInterface>
    </joint>
    <actuator name="rear_right_roller1_motor">
      <hardwareInterface>hardware_interface/EffortJointInterface</hardwareInterface>
      <mechanismReduction>1</mechanismReduction>
    </actuator>
  </transmission>
  <gazebo reference="rear_right_roller1_link">
    <mu1 value="0.8"/>
    <mu2 value="0.8"/>
    <kp value="10000000.0"/>
    <kd value="1.0"/>
    <fdir1 value="0 1 0"/>
  </gazebo>
  <transmission name="rear_right_wheel_trans">
    <type>transmission_interface/SimpleTransmission</type>
    <joint name="rear_right_wheel_joint">
      <hardwareInterface>hardware_interface/EffortJointInterface</hardwareInterface>
    </joint>
    <actuator name="rear_right_wheel_motor">
      <hardwareInterface>hardware_interface/EffortJointInterface</hardwareInterface>
      <mechanismReduction>1</mechanismReduction>
    </actuator>
  </transmission>
  <link name="rear_left_wheel_link">
    <visual>
      <origin rpy="0 0 0" xyz="0 0 0"/>
      <geometry>
        <mesh filename="package://mesh/visual/wheel.dae" scale="1 1 1"/>
      </geometry>
    </visual>
    <collision>
      <geometry>
        <mesh filename="package://mesh/collision/wheel.stl" scale="1 1 1"/>
      </geometry>
    </collision>
    <inertial>
      <origin xyz="0 0 0"/>
      <mass value="2.0"/>
      <inertia ixx="0.042025" ixy="0.0" ixz="0.0" iyy="0.024279" iyz="0.0" izz="0.024279"/>
    </inertial>
  </link>
  <gazebo reference="rear_left_wheel_link">
    <mu1 value="0.6"/>
    <mu2 value="0.6"/>
    <kp value="10000000.0"/>
    <kd value="1.0"/>
    <fdir1 value="0 1 0"/>
  </gazebo>
  <link name="rear_left_roller15_link">
    <visual>
      <origin rpy="0 0 0" xyz="0 0 0"/>
      <geometry>
        <mesh filename="package://mesh/visual/roller.dae" scale="1 1 1"/>
      </geometry>
    </visual>
    <collision>
      <geometry>
        <mesh filename="package://mesh/collision/roller.stl" scale="1 1 1"/>
      </geometry>
    </collision>
    <inertial>
      <origin xyz="0 0 0"/>
      <mass value="0.3"/>
      <inertia ixx="0.00024000" ixy="0.0" ixz="0.0" iyy="0.00076000" iyz="0.0" izz="0.00076000"/>
    </inertial>
  </link>
  <joint name="rear_left_roller15_joint" type="continuous">
    <origin rpy="0.5619350361043127 0.7022987807291682 -0.38630030387691144" xyz="0 0.08176231845901279 -0.03640292955528411"/>
    <axis xyz="1 0 0"/>
    <parent link="rear_left_wheel_link"/>
    <child link="rear_left_roller15_link"/>
    <dynamics damping="0.001" friction="0.0001"/>
  </joint>
  <transmission name="${name}_roller15_trans">
    <type>transmission_interface/SimpleTransmission</type>
    <joint name="rear_left_roller15_joint">
      <hardwareInterface>hardware_interface/EffortJointInterface</hardwareInterface>
    </joint>
    <actuator name="rear_left_roller15_motor">
      <hardwareInterface>hardware_interface/EffortJointInterface</hardwareInterface>
      <mechanismReduction>1</mechanismReduction>
    </actuator>
  </transmission>
  <gazebo reference="rear_left_roller15_link">
    <mu1 value="0.8"/>
    <mu2 value="0.8"/>
    <kp value="10000000.0"/>
    <kd value="1.0"/>
    <fdir1 value="0 1 0"/>
  </gazebo>
  <link name="rear_left_roller14_link">
    <visual>
      <origin rpy="0 0 0" xyz="0 0 0"/>
      <geometry>
        <mesh filename="package://mesh/visual/roller.dae" scale="1 1 1"/>
      </geometry>
    </visual>
    <collision>
      <geometry>
        <mesh filename="package://mesh/collision/roller.stl" scale="1 1 1"/>
      </geometry>
    </collision>
    <inertial>
      <origin xyz="0 0 0"/>
      <mass value="0.3"/>
      <inertia ixx="0.00024000" ixy="0.0" ixz="0.0" iyy="0.00076000" iyz="0.0" izz="0.00076000"/>
    </inertial>
  </link>
  <joint name="rear_left_roller14_joint" type="continuous">
    <origin rpy="1.0038406803226874 0.4928592704898482 -0.6390993414905143" xyz="0 0.05988718926911777 -0.06651146188022682"/>
    <axis xyz="1 0 0"/>
    <parent link="rear_left_wheel_link"/>
    <child link="rear_left_roller14_link"/>
    <dynamics damping="0.001" friction="0.0001"/>
  </joint>
  <transmission name="${name}_roller14_trans">
    <type>transmission_interface/SimpleTransmission</type>
    <joint name="rear_left_roller14_joint">
      <hardwareInterface>hardware_interface/EffortJointInterface</hardwareInterface>
    </joint>
    <actuator name="rear_left_roller14_motor">
      <hardwareInterface>hardware_interface/EffortJointInterface</hardwareInterface>
      <mechanismReduction>1</mechanismReduction>
    </actuator>
  </transmission>
  <gazebo reference="rear_left_roller14_link">
    <mu1 value="0.8"/>
    <mu2 value="0.8"/>
    <kp value="10000000.0"/>
    <kd value="1.0"/>
    <fdir1 value="0 1 0"/>
  </gazebo>
  <link name="rear_left_roller13_link">
    <visual>
      <origin rpy="0 0 0" xyz="0 0 0"/>
      <geometry>
        <mesh filename="package://mesh/visual/roller.dae" scale="1 1 1"/>
      </geometry>
    </visual>
    <collision>
      <geometry>
        <mesh filename="package://mesh/collision/roller.stl" scale="1 1 1"/>
      </geometry>
    </collision>
    <inertial>
      <origin xyz="0 0 0"/>
      <mass value="0.3"/>
      <inertia ixx="0.00024000" ixy="0.0" ixz="0.0" iyy="0.00076000" iyz="0.0" izz="0.00076000"/>
    </inertial>
  </link>
  <joint name="rear_left_roller13_joint" type="continuous">
    <origin rpy="1.3449626171032882 0.22028527385474703 -0.7603177925108144" xyz="0 0.027657020996557775 -0.08511955820841624"/>
    <axis xyz="1 0 0"/>
    <parent link="rear_left_wheel_link"/>
    <child link="rear_left_roller13_link"/>
    <dynamics damping="0.001" friction="0.0001"/>
  </joint>
  <transmission name="${name}_roller13_trans">
    <type>transmission_interface/SimpleTransmission</type>
    <joint name="rear_left_roller13_joint">
      <hardwareInterface>hardware_interface/EffortJointInterface</hardwareInterface>
    </joint>
    <actuator name="rear_left_roller13_motor">
      <hardwareInterface>hardware_interface/EffortJointInterface</hardwareInterface>
      <mechanismReduction>1</mechanismReduction>
    </actuator>
  </transmission>
  <gazebo reference="rear_left_roller13_link">
    <mu1 value="0.8"/>
    <mu2 value="0.8"/>
    <kp value="10000000.0"/>
    <kd value="1.0"/>
    <fdir1 value="0 1 0"/>
  </gazebo>
  <link name="rear_left_roller12_link">
    <visual>
      <origin rpy="0 0 0" xyz="0 0 0"/>
      <geometry>
        <mesh filename="package://mesh/visual/roller.dae" scale="1 1 1"/>
      </geometry>
    </visual>
    <collision>
      <geometry>
        <mesh filename="package://mesh/collision/roller.stl" scale="1 1 1"/>
      </geometry>
    </collision>
    <inertial>
      <origin xyz="0 0 0"/>
      <mass value="0.3"/>
      <inertia ixx="0.00024000" ixy="0.0" ixz="0.0" iyy="0.00076000" iyz="0.0" izz="0.00076000"/>
    </inertial>
  </link>
  <joint name="rear_left_roller12_joint" type="continuous">
    <origin rpy="-1.4966127917301506 -0.07398025001120935 -0.7826515949744619" xyz="0 -0.009355297462454976 -0.08900970963546047"/>
    <axis xyz="1 0 0"/>
    <parent link="rear_left_wheel_link"/>
    <child link="rear_left_roller12_link"/>
    <dynamics damping="0.001" friction="0.0001"/>
  </joint>
  <transmission name="${name}_roller12_trans">
    <type>transmission_interface/SimpleTransmission</type>
    <joint name="rear_left_roller12_joint">
      <hardwareInterface>hardware_interface/EffortJointInterface</hardwareInterface>
    </joint>
    <actuator name="rear_left_roller12_motor">
      <hardwareInterface>hardware_interface/EffortJointInterface</hardwareInterface>
      <mechanismReduction>1</mechanismReduction>
    </actuator>
  </transmission>
  <gazebo reference="rear_left_roller12_link">
    <mu1 value="0.8"/>
    <mu2 value="0.8"/>
    <kp value="10000000.0"/>
    <kd value="1.0"/>
    <fdir1 value="0 1 0"/>
  </gazebo>
  <link name="rear_left_roller11_link">
    <visual>
      <origin rpy="0 0 0" xyz="0 0 0"/>
      <geometry>
        <mesh filename="package://mesh/visual/roller.dae" scale="1 1 1"/>
      </geometry>
    </visual>
    <collision>
      <geometry>
        <mesh filename="package://mesh/collision/roller.stl" scale="1 1 1"/>
      </geometry>
    </collision>
    <inertial>
      <origin xyz="0 0 0"/>
      <mass value="0.3"/>
      <inertia ixx="0.00024000" ixy="0.0" ixz="0.0" iyy="0.00076000" iyz="0.0" izz="0.00076000"/>
    </inertial>
  </link>
  <joint name="rear_left_roller11_joint" type="continuous">
    <origin rpy="-1.1831996401397156 -0.3613671239067081 -0.7137243789447655" xyz="0 -0.04475000000000004 -0.07750927363870723"/>
    <axis xyz="1 0 0"/>
    <parent link="rear_left_wheel_link"/>
    <child link="rear_left_roller11_link"/>
    <dynamics damping="0.001" friction="0.0001"/>
  </joint>
  <transmission name="${name}_roller11_trans">
    <type>transmission_interface/SimpleTransmission</type>
    <joint name="rear_left_roller11_joint">
      <hardwareInterface>hardware_interface/EffortJointInterface</hardwareInterface>
    </joint>
    <actuator name="rear_left_roller11_motor">
      <hardwareInterface>hardware_interface/EffortJointInterface</hardwareInterface>
      <mechanismReduction>1</mechanismReduction>
    </actuator>
  </transmission>
  <gazebo reference="rear_left_roller11_link">
    <mu1 value="0.8"/>
    <mu2 value="0.8"/>
    <kp value="10000000.0"/>
    <kd value="1.0"/>
    <fdir1 value="0 1 0"/>
  </gazebo>
  <link name="rear_left_roller10_link">
    <visual>
      <origin rpy="0 0 0" xyz="0 0 0"/>
      <geometry>
        <mesh filename="package://mesh/visual/roller.dae" scale="1 1 1"/>
      </geometry>
    </visual>
    <collision>
      <geometry>
        <mesh filename="package://mesh/collision/roller.stl" scale="1 1 1"/>
      </geometry>
    </collision>
    <inertial>
      <origin xyz="0 0 0"/>
      <mass value="0.3"/>
      <inertia ixx="0.00024000" ixy="0.0" ixz="0.0" iyy="0.00076000" iyz="0.0" izz="0.00076000"/>
    </inertial>
  </link>
  <joint name="rear_left_roller10_joint" type="continuous">
    <origin rpy="-0.7989541677433551 -0.6090169187607924 -0.5313896516603533" xyz="0 -0.0724070209965578 -0.05260678008017634"/>
    <axis xyz="1 0 0"/>
    <parent link="rear_left_wheel_link"/>
    <child link="rear_left_roller10_link"/>
    <dynamics damping="0.001" friction="0.0001"/>
  </joint>
  <transmission name="${name}_roller10_trans">
    <type>transmission_interface/SimpleTransmission</type>
    <joint name="rear_left_roller10_joint">
      <hardwareInterface>hardware_interface/EffortJointInterface</hardwareInterface>
    </joint>
    <actuator name="rear_left_roller10_motor">
      <hardwareInterface>hardware_interface/EffortJointInterface</hardwareInterface>
      <mechanismReduction>1</mechanismReduction>
    </actuator>
  </transmission>
  <gazebo reference="rear_left_roller10_link">
    <mu1 value="0.8"/>
    <mu2 value="0.8"/>
    <kp value="10000000.0"/>
    <kd value="1.0"/>
    <fdir1 value="0 1 0"/>
  </gazebo>
  <link name="rear_left_roller9_link">
    <visual>
      <origin rpy="0 0 0" xyz="0 0 0"/>
      <geometry>
        <mesh filename="package://mesh/visual/roller.dae" scale="1 1 1"/>
      </geometry>
    </visual>
    <collision>
      <geometry>
        <mesh filename="package://mesh/collision/roller.stl" scale="1 1 1"/>
      </geometry>
    </collision>
    <inertial>
      <origin xyz="0 0 0"/>
      <mass value="0.3"/>
      <inertia ixx="0.00024000" ixy="0.0" ixz="0.0" iyy="0.00076000" iyz="0.0" izz="0.00076000"/>
    </inertial>
  </link>
  <joint name="rear_left_roller9_joint" type="continuous">
    <origin rpy="-0.29200750368454736 -0.7637777909460687 -0.20499125187874406" xyz="0 -0.08754421026567559 -0.018608096328189477"/>
    <axis xyz="1 0 0"/>
    <parent link="rear_left_wheel_link"/>
    <child link="rear_left_roller9_link"/>
    <dynamics damping="0.001" friction="0.0001"/>
  </joint>
  <transmission name="${name}_roller9_trans">
    <type>transmission_interface/SimpleTransmission</type>
    <joint name="rear_left_roller9_joint">
      <hardwareInterface>hardware_interface/EffortJointInterface</hardwareInterface>
    </joint>
    <actuator name="rear_left_roller9_motor">
      <hardwareInterface>hardware_interface/EffortJointInterface</hardwareInterface>
      <mechanismReduction>1</mechanismReduction>
    </actuator>
  </transmission>
  <gazebo reference="rear_left_roller9_link">
    <mu1 value="0.8"/>
    <mu2 value="0.8"/>
    <kp value="10000000.0"/>
    <kd value="1.0"/>
    <fdir1 value="0 1 0"/>
  </gazebo>
  <link name="rear_left_roller8_link">
    <visual>
      <origin rpy="0 0 0" xyz="0 0 0"/>
      <geometry>
        <mesh filename="package://mesh/visual/roller.dae" scale="1 1 1"/>
      </geometry>
    </visual>
    <collision>
      <geometry>
        <mesh filename="package://mesh/collision/roller.stl" scale="1 1 1"/>
      </geometry>
    </collision>
    <inertial>
      <origin xyz="0 0 0"/>
      <mass value="0.3"/>
      <inertia ixx="0.00024000" ixy="0.0" ixz="0.0" iyy="0.00076000" iyz="0.0" izz="0.00076000"/>
    </inertial>
  </link>
  <joint name="rear_left_roller8_joint" type="continuous">
    <origin rpy="0.2920075036845471 -0.7637777909460687 0.20499125187874387" xyz="0 -0.0875442102656756 0.01860809632818946"/>
    <axis xyz="1 0 0"/>
    <parent link="rear_left_wheel_link"/>
    <child link="rear_left_roller8_link"/>
    <dynamics damping="0.001" friction="0.0001"/>
  </joint>
  <transmission name="${name}_roller8_trans">
    <type>transmission_interface/SimpleTransmission</type>
    <joint name="rear_left_roller8_joint">
      <hardwareInterface>hardware_interface/EffortJointInterface</hardwareInterface>
    </joint>
    <actuator name="rear_left_roller8_motor">
      <hardwareInterface>hardware_interface/EffortJointInterface</hardwareInterface>
      <mechanismReduction>1</mechanismReduction>
    </actuator>
  </transmission>
  <gazebo reference="rear_left_roller8_link">
    <mu1 value="0.8"/>
    <mu2 value="0.8"/>
    <kp value="10000000.0"/>
    <kd value="1.0"/>
    <fdir1 value="0 1 0"/>
  </gazebo>
  <link name="rear_left_roller7_link">
    <visual>
      <origin rpy="0 0 0" xyz="0 0 0"/>
      <geometry>
        <mesh filename="package://mesh/visual/roller.dae" scale="1 1 1"/>
      </geometry>
    </visual>
    <collision>
      <geometry>
        <mesh filename="package://mesh/collision/roller.stl" scale="1 1 1"/>
      </geometry>
    </collision>
    <inertial>
      <origin xyz="0 0 0"/>
      <mass value="0.3"/>
      <inertia ixx="0.00024000" ixy="0.0" ixz="0.0" iyy="0.00076000" iyz="0.0" izz="0.00076000"/>
    </inertial>
  </link>
  <joint name="rear_left_roller7_joint" type="continuous">
    <origin rpy="0.7989541677433554 -0.6090169187607923 0.5313896516603536" xyz="0 -0.07240702099655778 0.05260678008017635"/>
    <axis xyz="1 0 0"/>
    <parent link="rear_left_wheel_link"/>
    <child link="rear_left_roller7_link"/>
    <dynamics damping="0.001" friction="0.0001"/>
  </joint>
  <transmission name="${name}_roller7_trans">
    <type>transmission_interface/SimpleTransmission</type>
    <joint name="rear_left_roller7_joint">
      <hardwareInterface>hardware_interface/EffortJointInterface</hardwareInterface>
    </joint>
    <actuator name="rear_left_roller7_motor">
      <hardwareInterface>hardware_interface/EffortJointInterface</hardwareInterface>
      <mechanismReduction>1</mechanismReduction>
    </actuator>
  </transmission>
  <gazebo reference="rear_left_roller7_link">
    <mu1 value="0.8"/>
    <mu2 value="0.8"/>
    <kp value="10000000.0"/>
    <kd value="1.0"/>
    <fdir1 value="0 1 0"/>
  </gazebo>
  <link name="rear_left_roller6_link">
    <visual>
      <origin rpy="0 0 0" xyz="0 0 0"/>
      <geometry>
        <mesh filename="package://mesh/visual/roller.dae" scale="1 1 1"/>
      </geometry>
    </visual>
    <collision>
      <geometry>
        <mesh filename="package://mesh/collision/roller.stl" scale="1 1 1"/>
      </geometry>
    </collision>
    <inertial>
      <origin xyz="0 0 0"/>
      <mass value="0.3"/>
      <inertia ixx="0.00024000" ixy="0.0" ixz="0.0" iyy="0.00076000" iyz="0.0" izz="0.00076000"/>
    </inertial>
  </link>
  <joint name="rear_left_roller6_joint" type="continuous">
    <origin rpy="1.1831996401397162 -0.3613671239067076 0.7137243789447657" xyz="0 -0.04474999999999998 0.07750927363870726"/>
    <axis xyz="1 0 0"/>
    <parent link="rear_left_wheel_link"/>
    <child link="rear_left_roller6_link"/>
    <dynamics damping="0.001" friction="0.0001"/>
  </joint>
  <transmission name="${name}_roller6_trans">
    <type>transmission_interface/SimpleTransmission</type>
    <joint name="rear_left_roller6_joint">
      <hardwareInterface>hardware_interface/EffortJointInterface</hardwareInterface>
    </joint>
    <actuator name="rear_left_roller6_motor">
      <hardwareInterface>hardware_interface/EffortJointInterface</hardwareInterface>
      <mechanismReduction>1</mechanismReduction>
    </actuator>
  </transmission>
  <gazebo reference="rear_left_roller6_link">
    <mu1 value="0.8"/>
    <mu2 value="0.8"/>
    <kp value="10000000.0"/>
    <kd value="1.0"/>
    <fdir1 value="0 1 0"/>
  </gazebo>
  <link name="rear_left_roller5_link">
    <visual>
      <origin rpy="0 0 0" xyz="0 0 0"/>
      <geometry>
        <mesh filename="package://mesh/visual/roller.dae" scale="1 1 1"/>
      </geometry>
    </visual>
    <collision>
      <geometry>
        <mesh filename="package://mesh/collision/roller.stl" scale="1 1 1"/>
      </geometry>
    </collision>
    <inertial>
      <origin xyz="0 0 0"/>
      <mass value="0.3"/>
      <inertia ixx="0.00024000" ixy="0.0" ixz="0.0" iyy="0.00076000" iyz="0.0" izz="0.00076000"/>
    </inertial>
  </link>
  <joint name="rear_left_roller5_joint" type="continuous">
    <origin rpy="1.4966127917301504 -0.07398025001120949 0.7826515949744619" xyz="0 -0.009355297462454993 0.08900970963546045"/>
    <axis xyz="1 0 0"/>
    <parent link="rear_left_wheel_link"/>
    <child link="rear_left_roller5_link"/>
    <dynamics damping="0.001" friction="0.0001"/>
  </joint>
  <transmission name="${name}_roller5_trans">
    <type>transmission_interface/SimpleTransmission</type>
    <joint name="rear_left_roller5_joint">
      <hardwareInterface>hardware_interface/EffortJointInterface</hardwareInterface>
    </joint>
    <actuator name="rear_left_roller5_motor">
      <hardwareInterface>hardware_interface/EffortJointInterface</hardwareInterface>
      <mechanismReduction>1</mechanismReduction>
    </actuator>
  </transmission>
  <gazebo reference="rear_left_roller5_link">
    <mu1 value="0.8"/>
    <mu2 value="0.8"/>
    <kp value="10000000.0"/>
    <kd value="1.0"/>
    <fdir1 value="0 1 0"/>
  </gazebo>
  <link name="rear_left_roller4_link">
    <visual>
      <origin rpy="0 0 0" xyz="0 0 0"/>
      <geometry>
        <mesh filename="package://mesh/visual/roller.dae" scale="1 1 1"/>
      </geometry>
    </visual>
    <collision>
      <geometry>
        <mesh filename="package://mesh/collision/roller.stl" scale="1 1 1"/>
      </geometry>
    </collision>
    <inertial>
      <origin xyz="0 0 0"/>
      <mass value="0.3"/>
      <inertia ixx="0.00024000" ixy="0.0" ixz="0.0" iyy="0.00076000" iyz="0.0" izz="0.00076000"/>
    </inertial>
  </link>
  <joint name="rear_left_roller4_joint" type="continuous">
    <origin rpy="-1.3449626171032882 0.2202852738547472 0.7603177925108144" xyz="0 0.027657020996557796 0.08511955820841624"/>
    <axis xyz="1 0 0"/>
    <parent link="rear_left_wheel_link"/>
    <child link="rear_left_roller4_link"/>
    <dynamics damping="0.001" friction="0.0001"/>
  </joint>
  <transmission name="${name}_roller4_trans">
    <type>transmission_interface/SimpleTransmission</type>
    <joint name="rear_left_roller4_joint">
      <hardwareInterface>hardware_interface/EffortJointInterface</hardwareInterface>
    </joint>
    <actuator name="rear_left_roller4_motor">
      <hardwareInterface>hardware_interface/EffortJointInterface</hardwareInterface>
      <mechanismReduction>1</mechanismReduction>
    </actuator>
  </transmission>
  <gazebo reference="rear_left_roller4_link">
    <mu1 value="0.8"/>
    <mu2 value="0.8"/>
    <kp value="10000000.0"/>
    <kd value="1.0"/>
    <fdir1 value="0 1 0"/>
  </gazebo>
  <link name="rear_left_roller3_link">
    <visual>
      <origin rpy="0 0 0" xyz="0 0 0"/>
      <geometry>
        <mesh filename="package://mesh/visual/roller.dae" scale="1 1 1"/>
      </geometry>
    </visual>
    <collision>
      <geometry>
        <mesh filename="package://mesh/collision/roller.stl" scale="1 1 1"/>
      </geometry>
    </collision>
    <inertial>
      <origin xyz="0 0 0"/>
      <mass value="0.3"/>
      <inertia ixx="0.00024000" ixy="0.0" ixz="0.0" iyy="0.00076000" iyz="0.0" izz="0.00076000"/>
    </inertial>
  </link>
  <joint name="rear_left_roller3_joint" type="continuous">
    <origin rpy="-1.0038406803226867 0.4928592704898485 0.6390993414905141" xyz="0 0.05988718926911781 0.06651146188022679"/>
    <axis xyz="1 0 0"/>
    <parent link="rear_left_wheel_link"/>
    <child link="rear_left_roller3_link"/>
    <dynamics damping="0.001" friction="0.0001"/>
  </joint>
  <transmission name="${name}_roller3_trans">
    <type>transmission_interface/SimpleTransmission</type>
    <joint name="rear_left_roller3_joint">
      <hardwareInterface>hardware_interface/EffortJointInterface</hardwareInterface>
    </joint>
    <actuator name="rear_left_roller3_motor">
      <hardwareInterface>hardware_interface/EffortJointInterface</hardwareInterface>
      <mechanismReduction>1</mechanismReduction>
    </actuator>
  </transmission>
  <gazebo reference="rear_left_roller3_link">
    <mu1 value="0.8"/>
    <mu2 value="0.8"/>
    <kp value="10000000.0"/>
    <kd value="1.0"/>
    <fdir1 value="0 1 0"/>
  </gazebo>
  <link name="rear_left_roller2_link">
    <visual>
      <origin rpy="0 0 0" xyz="0 0 0"/>
      <geometry>
        <mesh filename="package://mesh/visual/roller.dae" scale="1 1 1"/>
      </geometry>
    </visual>
    <collision>
      <geometry>
        <mesh filename="package://mesh/collision/roller.stl" scale="1 1 1"/>
      </geometry>
    </collision>
    <inertial>
      <origin xyz="0 0 0"/>
      <mass value="0.3"/>
      <inertia ixx="0.00024000" ixy="0.0" ixz="0.0" iyy="0.00076000" iyz="0.0" izz="0.00076000"/>
    </inertial>
  </link>
  <joint name="rear_left_roller2_joint" type="continuous">
    <origin rpy="-0.5619350361043128 0.702298780729168 0.3863003038769115" xyz="0 0.08176231845901277 0.03640292955528412"/>
    <axis xyz="1 0 0"/>
    <parent link="rear_left_wheel_link"/>
    <child link="rear_left_roller2_link"/>
    <dynamics damping="0.001" friction="0.0001"/>
  </joint>
  <transmission name="${name}_roller2_trans">
    <type>transmission_interface/SimpleTransmission</type>
    <joint name="rear_left_roller2_joint">
      <hardwareInterface>hardware_interface/EffortJointInterface</hardwareInterface>
    </joint>
    <actuator name="rear_left_roller2_motor">
      <hardwareInterface>hardware_interface/EffortJointInterface</hardwareInterface>
      <mechanismReduction>1</mechanismReduction>
    </actuator>
  </transmission>
  <gazebo reference="rear_left_roller2_link">
    <mu1 value="0.8"/>
    <mu2 value="0.8"/>
    <kp value="10000000.0"/>
    <kd value="1.0"/>
    <fdir1 value="0 1 0"/>
  </gazebo>
  <link name="rear_left_roller1_link">
    <visual>
      <origin rpy="0 0 0" xyz="0 0 0"/>
      <geometry>
        <mesh filename="package://mesh/visual/roller.dae" scale="1 1 1"/>
      </geometry>
    </visual>
    <collision>
      <geometry>
        <mesh filename="package://mesh/collision/roller.stl" scale="1 1 1"/>
      </geometry>
    </collision>
    <inertial>
      <origin xyz="0 0 0"/>
      <mass value="0.3"/>
      <inertia ixx="0.00024000" ixy="0.0" ixz="0.0" iyy="0.00076000" iyz="0.0" izz="0.00076000"/>
    </inertial>
  </link>
  <joint name="rear_left_roller1_joint" type="continuous">
    <origin rpy="-0.0 0.7853981633974482 0.0" xyz="0 0.0895 0.0"/>
    <axis xyz="1 0 0"/>
    <parent link="rear_left_wheel_link"/>
    <child link="rear_left_roller1_link"/>
    <dynamics damping="0.001" friction="0.0001"/>
  </joint>
  <transmission name="${name}_roller1_trans">
    <type>transmission_interface/SimpleTransmission</type>
    <joint name="rear_left_roller1_joint">
      <hardwareInterface>hardware_interface/EffortJointInterface</hardwareInterface>
    </joint>
    <actuator name="rear_left_roller1_motor">
      <hardwareInterface>hardware_interface/EffortJointInterface</hardwareInterface>
      <mechanismReduction>1</mechanismReduction>
    </actuator>
  </transmission>
  <gazebo reference="rear_left_roller1_link">
    <mu1 value="0.8"/>
    <mu2 value="0.8"/>
    <kp value="10000000.0"/>
    <kd value="1.0"/>
    <fdir1 value="0 1 0"/>
  </gazebo>
  <transmission name="rear_left_wheel_trans">
    <type>transmission_interface/SimpleTransmission</type>
    <joint name="rear_left_wheel_joint">
      <hardwareInterface>hardware_interface/EffortJointInterface</hardwareInterface>
    </joint>
    <actuator name="rear_left_wheel_motor">
      <hardwareInterface>hardware_interface/EffortJointInterface</hardwareInterface>
      <mechanismReduction>1</mechanismReduction>
    </actuator>
  </transmission>
  <!-- ===================== -->
  <!-- Wheel joints (auto-calculated origins) -->
  <!-- ===================== -->
  <joint name="front_right_wheel_joint" type="continuous">
    <origin rpy="0 0 1.5707963267948966" xyz="0.35000000000000003 -0.28500000000000003 -0.065"/>
    <axis xyz="1 0 0"/>
    <parent link="base_link"/>
    <child link="front_right_wheel_link"/>
  </joint>
  <joint name="front_left_wheel_joint" type="continuous">
    <origin rpy="0 0 1.5707963267948966" xyz="0.35000000000000003 0.28500000000000003 -0.065"/>
    <axis xyz="1 0 0"/>
    <parent link="base_link"/>
    <child link="front_left_wheel_link"/>
  </joint>
  <joint name="rear_right_wheel_joint" type="continuous">
    <origin rpy="0 0 1.5707963267948966" xyz="-0.35000000000000003 -0.28500000000000003 -0.065"/>
    <axis xyz="1 0 0"/>
    <parent link="base_link"/>
    <child link="rear_right_wheel_link"/>
  </joint>
  <joint name="rear_left_wheel_joint" type="continuous">
    <origin rpy="0 0 1.5707963267948966" xyz="-0.35000000000000003 0.28500000000000003 -0.065"/>
    <axis xyz="1 0 0"/>
    <parent link="base_link"/>
    <child link="rear_left_wheel_link"/>
  </joint>
  <!-- ===================== -->
  <!-- Gazebo ROS control plugin -->
  <!-- ===================== -->
  <gazebo>
    <plugin filename="libgazebo_ros_control.so" name="gazebo_ros_control">
      <robotNamespace>/</robotNamespace>
      <robotSimType>gazebo_ros_control/DefaultRobotHWSim</robotSimType>
      <legacyModeNS>true</legacyModeNS>
    </plugin>
  </gazebo>
</robot>

